Workbook

Sheet Comece Aqui
B2: MESA ÁGIL · PLANEJAMENTO FINANCEIRO · GUIA RÁPIDO | D2: ▦ DASHBOARD →
B4: 01 | C4: PREMISSAS — preços dos planos (já vêm do escopo), cenários de venda, custos variáveis, marketing e custos fixos. Os campos AMARELO-CLAROS você edita. | D4: ABRIR →
B5: 02 | C5: PREMISSAS › Cenário em uso — escolha Pessimista, Realista ou Otimista. Projeção, Fluxo de Caixa, Unit Economics e Dashboard passam a usar esse cenário. | D5: ABRIR →
B6: 03 | C6: PROJEÇÃO 24 MESES — clientes (novos, cancelados, ativos por plano), MRR, ARR, ticket médio, custos, margem bruta e lucro líquido mês a mês. | D6: ABRIR →
B7: 04 | C7: FLUXO DE CAIXA — separa o dinheiro das mensalidades do dinheiro do plano anual (que entra de uma vez) e mostra a receita anual ainda a reconhecer. | D7: ABRIR →
B8: 05 | C8: UNIT ECONOMICS — LTV, CAC, LTV/CAC e payback por plano e na média, mais o ponto de equilíbrio em número de clientes. | D8: ABRIR →
B9: 06 | C9: CENÁRIOS — os três cenários lado a lado, sempre calculados ao mesmo tempo, com gráficos comparativos. | D9: ABRIR →
B10: 07 | C10: DASHBOARD — resumo do cenário em uso: indicadores-chave e gráficos. Tudo automático. | D10: ABRIR →
B11: 08 | C11: MOTOR CENÁRIOS — cálculo automático que alimenta a aba Cenários. Não precisa mexer. | D11: ABRIR →
B13: IMPORTANTE | C13: Só os PREÇOS dos planos vieram do escopo. Todos os outros campos amarelo-claros (clientes, churn, mix, custos, marketing) são EXEMPLOS estimados para a planilha já sair funcionando — troque pelos seus dados reais.
B15: CORES | C15: Campos AMARELO-CLAROS com borda mostarda = você preenche (clique neles para ver uma dica). Células brancas = cálculo automático, não digite por cima. Vermelho = resultado negativo. Verde = resultado positivo.
B17: COMO LER | C17: Receita (MRR, lucro) é por COMPETÊNCIA: o plano anual é distribuído em 12 meses. Caixa é quando o dinheiro ENTRA: o plano anual entra inteiro no mês da venda/renovação. Clientes aparecem com casas decimais porque são médias estatísticas.
C19: Mesa Ágil (Powered by AIA) · comanda digital SaaS para barracas, food trucks, lanchonetes e restaurantes pequenos · mesaagil.pages.dev

Sheet Dashboard
B1: ⌂ Início
B2: ="DASHBOARD · "&UPPER(Premissas!$C$6)&" · CENÁRIO "&UPPER(Premissas!$C$9) -> DASHBOARD · MESA ÁGIL · CENÁRIO REALISTA
B3: Tudo automático, sempre no cenário em uso. Para trocar o cenário ou os números, vá em Premissas. | Q3: Premissas →
B5: PRINCIPAIS NÚMEROS · MÊS 24
B6: CLIENTES ATIVOS | E6: MRR | H6: ARR | K6: LUCRO LÍQUIDO | N6: LTV / CAC | Q6: PAYBACK DO CAC
B7: ='Projeção 24 meses'!$G$29 -> 338.01863 | E7: ='Projeção 24 meses'!$L$29 -> 21200.282 | H7: ='Projeção 24 meses'!$M$29 -> 254403.38 | K7: ='Projeção 24 meses'!$X$29 -> 12304.604 | N7: ='Unit Economics'!$K$18 -> 10.505223 | Q7: ='Unit Economics'!$L$18 -> 2.0768889
B8: no mês 24 | E8: ='Projeção 24 meses'!$L$17 -> 7530.4908 | H8: MRR × 12 | K8: no mês 24 | N8: ideal ≥ 3x | Q8: ideal ≤ 12 meses
B10: TICKET MÉDIO | E10: MARGEM BRUTA | H10: EQUILÍBRIO | K10: 1º MÊS COM LUCRO | N10: LUCRO ACUMULADO | Q10: MENOR SALDO DE CAIXA
B11: ='Projeção 24 meses'!$N$29 -> 62.719269 | E11: ='Projeção 24 meses'!$S$29 -> 0.89090935 | H11: ='Unit Economics'!$C$33 -> 61 | K11: ='Unit Economics'!$C$36 -> 46600 | N11: ='Projeção 24 meses'!$Y$29 -> 62578.916 | Q11: ='Fluxo de Caixa'!$G$34 -> -9905.4545
B12: ARPU | E12: após impostos, gateway, infra | H12: cobrem os custos fixos | K12: lucro líquido > 0 | N12: soma dos 24 meses | Q12: capital necessário
B14: RUMO AO EQUILÍBRIO
B15: Clientes ativos no mês 24 × clientes que cobrem os custos fixos | H15: =REPT("█",ROUND(MIN(1,MAX(0,N(O15)))*30,0))&REPT("░",30-ROUND(MIN(1,MAX(0,N(O15)))*30,0)) -> ██████████████████████████████ | O15: =IFERROR('Unit Economics'!$C$35/'Unit Economics'!$C$33,0) -> 5.541289 | P15: ='Unit Economics'!$C$33 -> 61
B17: EVOLUÇÃO EM 24 MESES
B52: ALERTAS
B53: =IF(V53,"✖ LTV/CAC abaixo de 3x — o cliente devolve pouco do que custa","✔ LTV/CAC saudável (3x ou mais)") -> ✔ LTV/CAC saudável (3x ou mais) | V53: ='Unit Economics'!$K$18<3 -> FALSE
B54: =IF(V54,"✖ Payback do CAC acima de 12 meses","✔ Payback do CAC em até 12 meses") -> ✔ Payback do CAC em até 12 meses | V54: ='Unit Economics'!$L$18>12 -> FALSE
B55: =IF(V55,"✖ O caixa fica negativo em algum mês — é preciso capital inicial","✔ O caixa nunca fica negativo") -> ✖ O caixa fica negativo em algum mês — é preciso capital inicial | V55: ='Fluxo de Caixa'!$G$34<0 -> TRUE
B56: =IF(V56,"✖ Ainda dá prejuízo no mês 24","✔ Operação lucrativa no mês 24") -> ✔ Operação lucrativa no mês 24 | V56: ='Projeção 24 meses'!$X$29<0 -> FALSE

Sheet Premissas
B1: ⌂ Início | C1: ▦ Dashboard
B2: PREMISSAS · TODOS OS CAMPOS EDITÁVEIS
B3: Campos AMARELO-CLAROS = você preenche. Preços dos planos vieram do escopo; o restante são exemplos para substituir pelos seus números.
B5: GERAL
B6: Nome do produto | C6: Mesa Ágil
B7: Mês de início da projeção | C7: 46296 | D7: Primeiro mês de vendas (mês 1 da projeção)
B8: Caixa inicial (R$) | C8: 0 | D8: Dinheiro já disponível no mês 1
B9: Cenário em uso | C9: Realista | D9: Pessimista, Realista ou Otimista — muda Projeção, Fluxo, Unit Economics e Dashboard
B11: PREÇOS DOS PLANOS (definidos no escopo)
B12: PLANO | C12: MENSAL | D12: DESCONTO ANUAL | E12: ANUAL (POR MÊS) | F12: ANUAL (COBRADO DE UMA VEZ) | G12: O QUE INCLUI
B13: Essencial | C13: 57.9 | D13: 0.15 | E13: =C13*(1-D13) -> 49.215 | F13: =ROUND(E13*12,2) -> 590.58 | G13: 1 barraca, lançar pedido, cozinha, chamada de senha, relatório do dia, histórico de 7 dias
B14: Pro | C14: 87.9 | D14: 0.2 | E14: =C14*(1-D14) -> 70.32 | F14: =ROUND(E14*12,2) -> 843.84 | G14: Tudo do Essencial + várias barracas, histórico completo, exportar, custo/lucro/taxas, suporte prioritário no WhatsApp
B15: No plano anual a RECEITA é reconhecida em 12 parcelas iguais (cobrado ÷ 12), mas o CAIXA entra inteiro no mês da venda.
B17: PREMISSAS DE VENDA POR CENÁRIO
B18: PREMISSA | C18: PESSIMISTA | D18: REALISTA | E18: OTIMISTA | F18: EM USO | G18: COMO PREENCHER
B19: Novos clientes pagantes no mês 1 | C19: 4 | D19: 8 | E19: 15 | F19: =INDEX(C19:E19,MATCH($C$9,$C$18:$E$18,0)) -> 8 | G19: Quantas assinaturas novas no primeiro mês de vendas
B20: Crescimento mensal dos novos clientes | C20: 0.03 | D20: 0.07 | E20: 0.12 | F20: =INDEX(C20:E20,MATCH($C$9,$C$18:$E$18,0)) -> 0.07 | G20: Quanto o nº de novos clientes cresce a cada mês. Ex.: 7% → 8; 8,6; 9,2...
B21: Churn mensal (plano mensal) | C21: 0.08 | D21: 0.05 | E21: 0.03 | F21: =INDEX(C21:E21,MATCH($C$9,$C$18:$E$18,0)) -> 0.05 | G21: % dos clientes do plano MENSAL que cancelam por mês
B22: Renovação do plano anual | C22: 0.5 | D22: 0.65 | E22: 0.8 | F22: =INDEX(C22:E22,MATCH($C$9,$C$18:$E$18,0)) -> 0.65 | G22: % dos clientes anuais que renovam ao fim dos 12 meses
B23: % dos novos clientes no plano Pro | C23: 0.15 | D23: 0.25 | E23: 0.35 | F23: =INDEX(C23:E23,MATCH($C$9,$C$18:$E$18,0)) -> 0.25 | G23: Mix de planos: o restante vai para o Essencial
B24: % dos novos clientes no plano anual | C24: 0.1 | D24: 0.2 | E24: 0.3 | F24: =INDEX(C24:E24,MATCH($C$9,$C$18:$E$18,0)) -> 0.2 | G24: Mix de cobrança: o restante paga mensal
B25: Conversão do teste grátis | C25: 0.1 | D25: 0.2 | E25: 0.3 | F25: =INDEX(C25:E25,MATCH($C$9,$C$18:$E$18,0)) -> 0.2 | G25: % dos testes grátis que viram pagantes. Sem teste grátis? Coloque 100%
B27: CUSTOS VARIÁVEIS POR CLIENTE
B28: Taxa do gateway de pagamento (%) | C28: 0.035 | D28: % cobrado pelo gateway (cartão/Pix/boleto) sobre cada cobrança. Média ponderada.
B29: Tarifa fixa por cobrança (R$) | C29: 0.49 | D29: Valor fixo por cobrança gerada (se houver). Mensal = 1 cobrança/mês; anual = 1 por ano.
B30: Imposto sobre faturamento (%) | C30: 0.06 | D30: Alíquota do Simples Nacional (SaaS costuma ser Anexo III, a partir de 6%). Confirme com o contador.
B31: Infraestrutura por cliente ativo (R$/mês) | C31: 0.5 | D31: Custo extra de servidor/banco/tempo real para cada cliente ativo.
B33: AQUISIÇÃO (MARKETING)
B34: Investimento em anúncios no mês 1 (R$) | C34: 1500 | D34: Meta/Google/Instagram pago no primeiro mês
B35: Crescimento mensal do investimento em anúncios | C35: 0.03 | D35: Quanto o orçamento de anúncios sobe por mês. 0% = fixo
B36: % dos novos clientes vindos de indicação/revenda | C36: 0.2 | D36: Parte dos novos clientes que gera comissão
B37: Comissão por cliente indicado (R$, paga uma vez) | C37: 30 | D37: Valor pago ao indicador/revendedor por cliente novo. 0 se não houver
B38: O CAC não é digitado: ele é calculado (anúncios + comissões ÷ novos clientes) na Projeção e no Unit Economics.
B40: CUSTOS FIXOS MENSAIS
B41: DESCRIÇÃO | C41: VALOR MENSAL | D41: A PARTIR DO MÊS | G41: OBSERVAÇÃO
B42: Hospedagem — Cloudflare Pages | C42: 0 | D42: 1 | G42: Plano gratuito atende no início
B43: Backend, banco de dados e tempo real | C43: 150 | D43: 1 | G43: Ex.: Supabase/Firebase pago (~US$ 25)
B44: Domínio | C44: 10 | D44: 1 | G44: Valor anual ÷ 12
B45: E-mail profissional | C45: 30 | D45: 1 | G45: Google Workspace, Zoho etc.
B46: Ferramentas de IA | C46: 110 | D46: 1 | G46: Assinaturas de IA usadas no desenvolvimento/atendimento
...

Sheet Projeção 24 meses
B1: ⌂ Início | C1: ▦ Dashboard
B2: ="PROJEÇÃO 24 MESES · CENÁRIO "&UPPER(Premissas!$C$9) -> PROJEÇÃO 24 MESES · CENÁRIO REALISTA
B3: Clientes, MRR, custos e lucro por COMPETÊNCIA (o plano anual é distribuído em 12 meses). Tudo automático — edite só a aba Premissas.
B4: CLIENTES | L4: RECEITA E RESULTADO | AC4: CÁLCULOS AUXILIARES
B5: Nº | C5: MÊS | D5: NOVOS CLIENTES | E5: TESTES GRÁTIS NECESSÁRIOS | F5: CANCELADOS | G5: CLIENTES ATIVOS | H5: ESSENCIAL MENSAL | I5: ESSENCIAL ANUAL | J5: PRO MENSAL | K5: PRO ANUAL | L5: MRR (RECEITA RECORRENTE) | M5: ARR (MRR × 12) | N5: TICKET MÉDIO (ARPU) | O5: IMPOSTOS | P5: GATEWAY | Q5: INFRA POR CLIENTE | R5: MARGEM BRUTA | S5: MARGEM BRUTA % | T5: CUSTOS FIXOS | U5: ANÚNCIOS | V5: COMISSÕES DE INDICAÇÃO | W5: CUSTOS TOTAIS | X5: LUCRO LÍQUIDO | Y5: LUCRO ACUMULADO | Z5: CAC DO MÊS | AA5: CLIENTES P/ EQUILÍBRIO | AC5: NOVOS ESS. MENSAL | AD5: NOVOS ESS. ANUAL | AE5: NOVOS PRO MENSAL | AF5: NOVOS PRO ANUAL | AG5: COBRANÇAS ANUAIS ESS. (NOVOS + RENOV.) | AH5: COBRANÇAS ANUAIS PRO (NOVOS + RENOV.) | AI5: ANUAIS QUE NÃO RENOVARAM | AJ5: Nº DE COBRANÇAS NO MÊS | AK5: MÊS COM LUCRO?
B6: =1 -> 1 | C6: =EDATE(Premissas!$C$7,B6-1) -> 46296 | D6: =Premissas!$F$19*(1+Premissas!$F$20)^(B6-1) -> 8 | E6: =IFERROR(D6/Premissas!$F$25,0) -> 40 | F6: =(N(H5)+N(J5))*Premissas!$F$21+AI6 -> 0 | G6: =H6+I6+J6+K6 -> 8 | H6: =N(H5)*(1-Premissas!$F$21)+AC6 -> 4.8 | I6: =SUM(INDEX($AG$6:$AG$29,MAX(1,B6-11)):INDEX($AG$6:$AG$29,B6)) -> 1.2 | J6: =N(J5)*(1-Premissas!$F$21)+AE6 -> 1.6 | K6: =SUM(INDEX($AH$6:$AH$29,MAX(1,B6-11)):INDEX($AH$6:$AH$29,B6)) -> 0.4 | L6: =H6*Premissas!$C$13+I6*Premissas!$F$13/12+J6*Premissas!$C$14+K6*Premissas!$F$14/12 -> 505.746 | M6: =L6*12 -> 6068.952 | N6: =IFERROR(L6/G6,0) -> 63.21825 | O6: =L6*Premissas!$C$30 -> 30.34476 | P6: =L6*Premissas!$C$28+AJ6*Premissas!$C$29 -> 21.62111 | Q6: =G6*Premissas!$C$31 -> 4 | R6: =L6-O6-P6-Q6 -> 449.78013 | S6: =IFERROR(R6/L6,0) -> 0.88933997 | T6: =SUMPRODUCT(Premissas!$C$42:$C$61,--(Premissas!$D$42:$D$61<=B6)) -> 2195 | U6: =Premissas!$C$34*(1+Premissas!$C$35)^(B6-1) -> 1500 | V6: =D6*Premissas!$C$36*Premissas!$C$37 -> 48 | W6: =O6+P6+Q6+T6+U6+V6 -> 3798.9659 | X6: =L6-W6 -> -3293.2199 | Y6: =N(Y5)+X6 -> -3293.2199 | Z6: =IFERROR((U6+V6)/D6,0) -> 193.5 | AA6: =IFERROR(T6/(R6/G6),0) -> 39.041298 | AC6: =D6*(1-Premissas!$F$23)*(1-Premissas!$F$24) -> 4.8 | AD6: =D6*(1-Premissas!$F$23)*Premissas!$F$24 -> 1.2 | AE6: =D6*Premissas!$F$23*(1-Premissas!$F$24) -> 1.6 | AF6: =D6*Premissas!$F$23*Premissas!$F$24 -> 0.4 | AG6: =AD6+IF(B6>12,INDEX($AD$6:$AD$29,B6-12)*Premissas!$F$22,0) -> 1.2 | AH6: =AF6+IF(B6>12,INDEX($AF$6:$AF$29,B6-12)*Premissas!$F$22,0) -> 0.4 | AI6: =IF(B6>12,(INDEX($AD$6:$AD$29,B6-12)+INDEX($AF$6:$AF$29,B6-12))*(1-Premissas!$F$22),0) -> 0 | AJ6: =H6+J6+AG6+AH6 -> 8 | AK6: =IF(X6>0,B6,"")
B7: =B6+1 -> 2 | C7: =EDATE(Premissas!$C$7,B7-1) -> 46327 | D7: =Premissas!$F$19*(1+Premissas!$F$20)^(B7-1) -> 8.56 | E7: =IFERROR(D7/Premissas!$F$25,0) -> 42.8 | F7: =(N(H6)+N(J6))*Premissas!$F$21+AI7 -> 0.32 | G7: =H7+I7+J7+K7 -> 16.24 | H7: =N(H6)*(1-Premissas!$F$21)+AC7 -> 9.696 | I7: =SUM(INDEX($AG$6:$AG$29,MAX(1,B7-11)):INDEX($AG$6:$AG$29,B7)) -> 2.484 | J7: =N(J6)*(1-Premissas!$F$21)+AE7 -> 3.232 | K7: =SUM(INDEX($AH$6:$AH$29,MAX(1,B7-11)):INDEX($AH$6:$AH$29,B7)) -> 0.828 | L7: =H7*Premissas!$C$13+I7*Premissas!$F$13/12+J7*Premissas!$C$14+K7*Premissas!$F$14/12 -> 1025.9662 | M7: =L7*12 -> 12311.595 | N7: =IFERROR(L7/G7,0) -> 63.17526 | O7: =L7*Premissas!$C$30 -> 61.557973 | P7: =L7*Premissas!$C$28+AJ7*Premissas!$C$29 -> 43.082418 | Q7: =G7*Premissas!$C$31 -> 8.12 | R7: =L7-O7-P7-Q7 -> 913.20583 | S7: =IFERROR(R7/L7,0) -> 0.89009347 | T7: =SUMPRODUCT(Premissas!$C$42:$C$61,--(Premissas!$D$42:$D$61<=B7)) -> 2195 | U7: =Premissas!$C$34*(1+Premissas!$C$35)^(B7-1) -> 1545 | V7: =D7*Premissas!$C$36*Premissas!$C$37 -> 51.36 | W7: =O7+P7+Q7+T7+U7+V7 -> 3904.1204 | X7: =L7-W7 -> -2878.1542 | Y7: =N(Y6)+X7 -> -6171.374 | Z7: =IFERROR((U7+V7)/D7,0) -> 186.49065 | AA7: =IFERROR(T7/(R7/G7),0) -> 39.034792 | AC7: =D7*(1-Premissas!$F$23)*(1-Premissas!$F$24) -> 5.136 | AD7: =D7*(1-Premissas!$F$23)*Premissas!$F$24 -> 1.284 | AE7: =D7*Premissas!$F$23*(1-Premissas!$F$24) -> 1.712 | AF7: =D7*Premissas!$F$23*Premissas!$F$24 -> 0.428 | AG7: =AD7+IF(B7>12,INDEX($AD$6:$AD$29,B7-12)*Premissas!$F$22,0) -> 1.284 | AH7: =AF7+IF(B7>12,INDEX($AF$6:$AF$29,B7-12)*Premissas!$F$22,0) -> 0.428 | AI7: =IF(B7>12,(INDEX($AD$6:$AD$29,B7-12)+INDEX($AF$6:$AF$29,B7-12))*(1-Premissas!$F$22),0) -> 0 | AJ7: =H7+J7+AG7+AH7 -> 14.64 | AK7: =IF(X7>0,B7,"")
B8: =B7+1 -> 3 | C8: =EDATE(Premissas!$C$7,B8-1) -> 46357 | D8: =Premissas!$F$19*(1+Premissas!$F$20)^(B8-1) -> 9.1592 | E8: =IFERROR(D8/Premissas!$F$25,0) -> 45.796 | F8: =(N(H7)+N(J7))*Premissas!$F$21+AI8 -> 0.6464 | G8: =H8+I8+J8+K8 -> 24.7528 | H8: =N(H7)*(1-Premissas!$F$21)+AC8 -> 14.70672 | I8: =SUM(INDEX($AG$6:$AG$29,MAX(1,B8-11)):INDEX($AG$6:$AG$29,B8)) -> 3.85788 | J8: =N(J7)*(1-Premissas!$F$21)+AE8 -> 4.90224 | K8: =SUM(INDEX($AH$6:$AH$29,MAX(1,B8-11)):INDEX($AH$6:$AH$29,B8)) -> 1.28596 | L8: =H8*Premissas!$C$13+I8*Premissas!$F$13/12+J8*Premissas!$C$14+K8*Premissas!$F$14/12 -> 1562.7203 | M8: =L8*12 -> 18752.643 | N8: =IFERROR(L8/G8,0) -> 63.13307 | O8: =L8*Premissas!$C$30 -> 93.763215 | P8: =L8*Premissas!$C$28+AJ8*Premissas!$C$29 -> 65.201201 | Q8: =G8*Premissas!$C$31 -> 12.3764 | R8: =L8-O8-P8-Q8 -> 1391.3794 | S8: =IFERROR(R8/L8,0) -> 0.89035733 | T8: =SUMPRODUCT(Premissas!$C$42:$C$61,--(Premissas!$D$42:$D$61<=B8)) -> 2195 | U8: =Premissas!$C$34*(1+Premissas!$C$35)^(B8-1) -> 1591.35 | V8: =D8*Premissas!$C$36*Premissas!$C$37 -> 54.9552 | W8: =O8+P8+Q8+T8+U8+V8 -> 4012.646 | X8: =L8-W8 -> -2449.9258 | Y8: =N(Y7)+X8 -> -8621.2998 | Z8: =IFERROR((U8+V8)/D8,0) -> 179.74334 | AA8: =IFERROR(T8/(R8/G8),0) -> 39.049302 | AC8: =D8*(1-Premissas!$F$23)*(1-Premissas!$F$24) -> 5.49552 | AD8: =D8*(1-Premissas!$F$23)*Premissas!$F$24 -> 1.37388 | AE8: =D8*Premissas!$F$23*(1-Premissas!$F$24) -> 1.83184 | AF8: =D8*Premissas!$F$23*Premissas!$F$24 -> 0.45796 | AG8: =AD8+IF(B8>12,INDEX($AD$6:$AD$29,B8-12)*Premissas!$F$22,0) -> 1.37388 | AH8: =AF8+IF(B8>12,INDEX($AF$6:$AF$29,B8-12)*Premissas!$F$22,0) -> 0.45796 | AI8: =IF(B8>12,(INDEX($AD$6:$AD$29,B8-12)+INDEX($AF$6:$AF$29,B8-12))*(1-Premissas!$F$22),0) -> 0 | AJ8: =H8+J8+AG8+AH8 -> 21.4408 | AK8: =IF(X8>0,B8,"")
B9: =B8+1 -> 4 | C9: =EDATE(Premissas!$C$7,B9-1) -> 46388 | D9: =Premissas!$F$19*(1+Premissas!$F$20)^(B9-1) -> 9.800344 | E9: =IFERROR(D9/Premissas!$F$25,0) -> 49.00172 | F9: =(N(H8)+N(J8))*Premissas!$F$21+AI9 -> 0.980448 | G9: =H9+I9+J9+K9 -> 33.572696 | H9: =N(H8)*(1-Premissas!$F$21)+AC9 -> 19.85159 | I9: =SUM(INDEX($AG$6:$AG$29,MAX(1,B9-11)):INDEX($AG$6:$AG$29,B9)) -> 5.3279316 | J9: =N(J8)*(1-Premissas!$F$21)+AE9 -> 6.6171968 | K9: =SUM(INDEX($AH$6:$AH$29,MAX(1,B9-11)):INDEX($AH$6:$AH$29,B9)) -> 1.7759772 | L9: =H9*Premissas!$C$13+I9*Premissas!$F$13/12+J9*Premissas!$C$14+K9*Premissas!$F$14/12 -> 2118.1596 | M9: =L9*12 -> 25417.915 | N9: =IFERROR(L9/G9,0) -> 63.091732 | O9: =L9*Premissas!$C$30 -> 127.08957 | P9: =L9*Premissas!$C$28+AJ9*Premissas!$C$29 -> 88.065724 | Q9: =G9*Premissas!$C$31 -> 16.786348 | R9: =L9-O9-P9-Q9 -> 1886.2179 | S9: =IFERROR(R9/L9,0) -> 0.8904985 | T9: =SUMPRODUCT(Premissas!$C$42:$C$61,--(Premissas!$D$42:$D$61<=B9)) -> 2195 | U9: =Premissas!$C$34*(1+Premissas!$C$35)^(B9-1) -> 1639.0905 | V9: =D9*Premissas!$C$36*Premissas!$C$37 -> 58.802064 | W9: =O9+P9+Q9+T9+U9+V9 -> 4124.8342 | X9: =L9-W9 -> -2006.6747 | Y9: =N(Y8)+X9 -> -10627.974 | Z9: =IFERROR((U9+V9)/D9,0) -> 173.24826 | AA9: =IFERROR(T9/(R9/G9),0) -> 39.068693 | AC9: =D9*(1-Premissas!$F$23)*(1-Premissas!$F$24) -> 5.8802064 | AD9: =D9*(1-Premissas!$F$23)*Premissas!$F$24 -> 1.4700516 | AE9: =D9*Premissas!$F$23*(1-Premissas!$F$24) -> 1.9600688 | AF9: =D9*Premissas!$F$23*Premissas!$F$24 -> 0.4900172 | AG9: =AD9+IF(B9>12,INDEX($AD$6:$AD$29,B9-12)*Premissas!$F$22,0) -> 1.4700516 | AH9: =AF9+IF(B9>12,INDEX($AF$6:$AF$29,B9-12)*Premissas!$F$22,0) -> 0.4900172 | AI9: =IF(B9>12,(INDEX($AD$6:$AD$29,B9-12)+INDEX($AF$6:$AF$29,B9-12))*(1-Premissas!$F$22),0) -> 0 | AJ9: =H9+J9+AG9+AH9 -> 28.428856 | AK9: =IF(X9>0,B9,"")
B10: =B9+1 -> 5 | C10: =EDATE(Premissas!$C$7,B10-1) -> 46419 | D10: =Premissas!$F$19*(1+Premissas!$F$20)^(B10-1) -> 10.486368 | E10: =IFERROR(D10/Premissas!$F$25,0) -> 52.43184 | F10: =(N(H9)+N(J9))*Premissas!$F$21+AI10 -> 1.3234394 | G10: =H10+I10+J10+K10 -> 42.735625 | H10: =N(H9)*(1-Premissas!$F$21)+AC10 -> 25.150832 | I10: =SUM(INDEX($AG$6:$AG$29,MAX(1,B10-11)):INDEX($AG$6:$AG$29,B10)) -> 6.9008868 | J10: =N(J9)*(1-Premissas!$F$21)+AE10 -> 8.3836106 | K10: =SUM(INDEX($AH$6:$AH$29,MAX(1,B10-11)):INDEX($AH$6:$AH$29,B10)) -> 2.3002956 | L10: =H10*Premissas!$C$13+I10*Premissas!$F$13/12+J10*Premissas!$C$14+K10*Premissas!$F$14/12 -> 2694.5365 | M10: =L10*12 -> 32334.437 | N10: =IFERROR(L10/G10,0) -> 63.051294 | O10: =L10*Premissas!$C$30 -> 161.67219 | P10: =L10*Premissas!$C$28+AJ10*Premissas!$C$29 -> 111.76832 | Q10: =G10*Premissas!$C$31 -> 21.367812 | R10: =L10-O10-P10-Q10 -> 2399.7281 | S10: =IFERROR(R10/L10,0) -> 0.89059034 | T10: =SUMPRODUCT(Premissas!$C$42:$C$61,--(Premissas!$D$42:$D$61<=B10)) -> 2195 | U10: =Premissas!$C$34*(1+Premissas!$C$35)^(B10-1) -> 1688.2632 | V10: =D10*Premissas!$C$36*Premissas!$C$37 -> 62.918208 | W10: =O10+P10+Q10+T10+U10+V10 -> 4240.9897 | X10: =L10-W10 -> -1546.4533 | Y10: =N(Y9)+X10 -> -12174.428 | Z10: =IFERROR((U10+V10)/D10,0) -> 166.99599 | AA10: =IFERROR(T10/(R10/G10),0) -> 39.089718 | AC10: =D10*(1-Premissas!$F$23)*(1-Premissas!$F$24) -> 6.2918208 | AD10: =D10*(1-Premissas!$F$23)*Premissas!$F$24 -> 1.5729552 | AE10: =D10*Premissas!$F$23*(1-Premissas!$F$24) -> 2.0972736 | AF10: =D10*Premissas!$F$23*Premissas!$F$24 -> 0.5243184 | AG10: =AD10+IF(B10>12,INDEX($AD$6:$AD$29,B10-12)*Premissas!$F$22,0) -> 1.5729552 | AH10: =AF10+IF(B10>12,INDEX($AF$6:$AF$29,B10-12)*Premissas!$F$22,0) -> 0.5243184 | AI10: =IF(B10>12,(INDEX($AD$6:$AD$29,B10-12)+INDEX($AF$6:$AF$29,B10-12))*(1-Premissas!$F$22),0) -> 0 | AJ10: =H10+J10+AG10+AH10 -> 35.631716 | AK10: =IF(X10>0,B10,"")
B11: =B10+1 -> 6 | C11: =EDATE(Premissas!$C$7,B11-1) -> 46447 | D11: =Premissas!$F$19*(1+Premissas!$F$20)^(B11-1) -> 11.220414 | E11: =IFERROR(D11/Premissas!$F$25,0) -> 56.102069 | F11: =(N(H10)+N(J10))*Premissas!$F$21+AI11 -> 1.6767221 | G11: =H11+I11+J11+K11 -> 52.279316 | H11: =N(H10)*(1-Premissas!$F$21)+AC11 -> 30.625538 | I11: =SUM(INDEX($AG$6:$AG$29,MAX(1,B11-11)):INDEX($AG$6:$AG$29,B11)) -> 8.5839489 | J11: =N(J10)*(1-Premissas!$F$21)+AE11 -> 10.208513 | K11: =SUM(INDEX($AH$6:$AH$29,MAX(1,B11-11)):INDEX($AH$6:$AH$29,B11)) -> 2.8613163 | L11: =H11*Premissas!$C$13+I11*Premissas!$F$13/12+J11*Premissas!$C$14+K11*Premissas!$F$14/12 -> 3294.2138 | M11: =L11*12 -> 39530.565 | N11: =IFERROR(L11/G11,0) -> 63.011799 | O11: =L11*Premissas!$C$30 -> 197.65283 | P11: =L11*Premissas!$C$28+AJ11*Premissas!$C$29 -> 136.40577 | Q11: =G11*Premissas!$C$31 -> 26.139658 | R11: =L11-O11-P11-Q11 -> 2934.0155 | S11: =IFERROR(R11/L11,0) -> 0.89065729 | T11: =SUMPRODUCT(Premissas!$C$42:$C$61,--(Premissas!$D$42:$D$61<=B11)) -> 2195 | U11: =Premissas!$C$34*(1+Premissas!$C$35)^(B11-1) -> 1738.9111 | V11: =D11*Premissas!$C$36*Premissas!$C$37 -> 67.322483 | W11: =O11+P11+Q11+T11+U11+V11 -> 4361.4318 | X11: =L11-W11 -> -1067.2181 | Y11: =N(Y10)+X11 -> -13241.646 | Z11: =IFERROR((U11+V11)/D11,0) -> 160.97745 | AA11: =IFERROR(T11/(R11/G11),0) -> 39.111279 | AC11: =D11*(1-Premissas!$F$23)*(1-Premissas!$F$24) -> 6.7322483 | AD11: =D11*(1-Premissas!$F$23)*Premissas!$F$24 -> 1.6830621 | AE11: =D11*Premissas!$F$23*(1-Premissas!$F$24) -> 2.2440828 | AF11: =D11*Premissas!$F$23*Premissas!$F$24 -> 0.56102069 | AG11: =AD11+IF(B11>12,INDEX($AD$6:$AD$29,B11-12)*Premissas!$F$22,0) -> 1.6830621 | AH11: =AF11+IF(B11>12,INDEX($AF$6:$AF$29,B11-12)*Premissas!$F$22,0) -> 0.56102069 | AI11: =IF(B11>12,(INDEX($AD$6:$AD$29,B11-12)+INDEX($AF$6:$AF$29,B11-12))*(1-Premissas!$F$22),0) -> 0 | AJ11: =H11+J11+AG11+AH11 -> 43.078134 | AK11: =IF(X11>0,B11,"")
B12: =B11+1 -> 7 | C12: =EDATE(Premissas!$C$7,B12-1) -> 46478 | D12: =Premissas!$F$19*(1+Premissas!$F$20)^(B12-1) -> 12.005843 | E12: =IFERROR(D12/Premissas!$F$25,0) -> 60.029214 | F12: =(N(H11)+N(J11))*Premissas!$F$21+AI12 -> 2.0417026 | G12: =H12+I12+J12+K12 -> 62.243457 | H12: =N(H11)*(1-Premissas!$F$21)+AC12 -> 36.297767 | I12: =SUM(INDEX($AG$6:$AG$29,MAX(1,B12-11)):INDEX($AG$6:$AG$29,B12)) -> 10.384825 | J12: =N(J11)*(1-Premissas!$F$21)+AE12 -> 12.099256 | K12: =SUM(INDEX($AH$6:$AH$29,MAX(1,B12-11)):INDEX($AH$6:$AH$29,B12)) -> 3.4616084 | L12: =H12*Premissas!$C$13+I12*Premissas!$F$13/12+J12*Premissas!$C$14+K12*Premissas!$F$14/12 -> 3919.6748 | M12: =L12*12 -> 47036.097 | N12: =IFERROR(L12/G12,0) -> 62.973283 | O12: =L12*Premissas!$C$30 -> 235.18049 | P12: =L12*Premissas!$C$28+AJ12*Premissas!$C$29 -> 162.07973 | Q12: =G12*Premissas!$C$31 -> 31.121728 | R12: =L12-O12-P12-Q12 -> 3491.2928 | S12: =IFERROR(R12/L12,0) -> 0.89070982 | T12: =SUMPRODUCT(Premissas!$C$42:$C$61,--(Premissas!$D$42:$D$61<=B12)) -> 3395 | U12: =Premissas!$C$34*(1+Premissas!$C$35)^(B12-1) -> 1791.0784 | V12: =D12*Premissas!$C$36*Premissas!$C$37 -> 72.035057 | W12: =O12+P12+Q12+T12+U12+V12 -> 5686.4954 | X12: =L12-W12 -> -1766.8207 | Y12: =N(Y11)+X12 -> -15008.466 | Z12: =IFERROR((U12+V12)/D12,0) -> 155.1839 | AA12: =IFERROR(T12/(R12/G12),0) -> 60.526729 | AC12: =D12*(1-Premissas!$F$23)*(1-Premissas!$F$24) -> 7.2035057 | AD12: =D12*(1-Premissas!$F$23)*Premissas!$F$24 -> 1.8008764 | AE12: =D12*Premissas!$F$23*(1-Premissas!$F$24) -> 2.4011686 | AF12: =D12*Premissas!$F$23*Premissas!$F$24 -> 0.60029214 | AG12: =AD12+IF(B12>12,INDEX($AD$6:$AD$29,B12-12)*Premissas!$F$22,0) -> 1.8008764 | AH12: =AF12+IF(B12>12,INDEX($AF$6:$AF$29,B12-12)*Premissas!$F$22,0) -> 0.60029214 | AI12: =IF(B12>12,(INDEX($AD$6:$AD$29,B12-12)+INDEX($AF$6:$AF$29,B12-12))*(1-Premissas!$F$22),0) -> 0 | AJ12: =H12+J12+AG12+AH12 -> 50.798192 | AK12: =IF(X12>0,B12,"")
B13: =B12+1 -> 8 | C13: =EDATE(Premissas!$C$7,B13-1) -> 46508 | D13: =Premissas!$F$19*(1+Premissas!$F$20)^(B13-1) -> 12.846252 | E13: =IFERROR(D13/Premissas!$F$25,0) -> 64.231259 | F13: =(N(H12)+N(J12))*Premissas!$F$21+AI13 -> 2.4198511 | G13: =H13+I13+J13+K13 -> 72.669857 | H13: =N(H12)*(1-Premissas!$F$21)+AC13 -> 42.19063 | I13: =SUM(INDEX($AG$6:$AG$29,MAX(1,B13-11)):INDEX($AG$6:$AG$29,B13)) -> 12.311763 | J13: =N(J12)*(1-Premissas!$F$21)+AE13 -> 14.063543 | K13: =SUM(INDEX($AH$6:$AH$29,MAX(1,B13-11)):INDEX($AH$6:$AH$29,B13)) -> 4.103921 | L13: =H13*Premissas!$C$13+I13*Premissas!$F$13/12+J13*Premissas!$C$14+K13*Premissas!$F$14/12 -> 4573.5341 | M13: =L13*12 -> 54882.409 | N13: =IFERROR(L13/G13,0) -> 62.935779 | O13: =L13*Premissas!$C$30 -> 274.41204 | P13: =L13*Premissas!$C$28+AJ13*Premissas!$C$29 -> 188.89717 | Q13: =G13*Premissas!$C$31 -> 36.334929 | R13: =L13-O13-P13-Q13 -> 4073.8899 | S13: =IFERROR(R13/L13,0) -> 0.89075316 | T13: =SUMPRODUCT(Premissas!$C$42:$C$61,--(Premissas!$D$42:$D$61<=B13)) -> 3395 | U13: =Premissas!$C$34*(1+Premissas!$C$35)^(B13-1) -> 1844.8108 | V13: =D13*Premissas!$C$36*Premissas!$C$37 -> 77.077511 | W13: =O13+P13+Q13+T13+U13+V13 -> 5816.5325 | X13: =L13-W13 -> -1242.9984 | Y13: =N(Y12)+X13 -> -16251.465 | Z13: =IFERROR((U13+V13)/D13,0) -> 149.60693 | AA13: =IFERROR(T13/(R13/G13),0) -> 60.559851 | AC13: =D13*(1-Premissas!$F$23)*(1-Premissas!$F$24) -> 7.7077511 | AD13: =D13*(1-Premissas!$F$23)*Premissas!$F$24 -> 1.9269378 | AE13: =D13*Premissas!$F$23*(1-Premissas!$F$24) -> 2.5692504 | AF13: =D13*Premissas!$F$23*Premissas!$F$24 -> 0.64231259 | AG13: =AD13+IF(B13>12,INDEX($AD$6:$AD$29,B13-12)*Premissas!$F$22,0) -> 1.9269378 | AH13: =AF13+IF(B13>12,INDEX($AF$6:$AF$29,B13-12)*Premissas!$F$22,0) -> 0.64231259 | AI13: =IF(B13>12,(INDEX($AD$6:$AD$29,B13-12)+INDEX($AF$6:$AF$29,B13-12))*(1-Premissas!$F$22),0) -> 0 | AJ13: =H13+J13+AG13+AH13 -> 58.823424 | AK13: =IF(X13>0,B13,"")
B14: =B13+1 -> 9 | C14: =EDATE(Premissas!$C$7,B14-1) -> 46539 | D14: =Premissas!$F$19*(1+Premissas!$F$20)^(B14-1) -> 13.745489 | E14: =IFERROR(D14/Premissas!$F$25,0) -> 68.727447 | F14: =(N(H13)+N(J13))*Premissas!$F$21+AI14 -> 2.8127087 | G14: =H14+I14+J14+K14 -> 83.602638 | H14: =N(H13)*(1-Premissas!$F$21)+AC14 -> 48.328392 | I14: =SUM(INDEX($AG$6:$AG$29,MAX(1,B14-11)):INDEX($AG$6:$AG$29,B14)) -> 14.373586 | J14: =N(J13)*(1-Premissas!$F$21)+AE14 -> 16.109464 | K14: =SUM(INDEX($AH$6:$AH$29,MAX(1,B14-11)):INDEX($AH$6:$AH$29,B14)) -> 4.7911955 | L14: =H14*Premissas!$C$13+I14*Premissas!$F$13/12+J14*Premissas!$C$14+K14*Premissas!$F$14/12 -> 5258.5487 | M14: =L14*12 -> 63102.585 | N14: =IFERROR(L14/G14,0) -> 62.899316 | O14: =L14*Premissas!$C$30 -> 315.51292 | P14: =L14*Premissas!$C$28+AJ14*Premissas!$C$29 -> 216.97081 | Q14: =G14*Premissas!$C$31 -> 41.801319 | R14: =L14-O14-P14-Q14 -> 4684.2637 | S14: =IFERROR(R14/L14,0) -> 0.8907902 | T14: =SUMPRODUCT(Premissas!$C$42:$C$61,--(Premissas!$D$42:$D$61<=B14)) -> 3395 | U14: =Premissas!$C$34*(1+Premissas!$C$35)^(B14-1) -> 1900.1551 | V14: =D14*Premissas!$C$36*Premissas!$C$37 -> 82.472937 | W14: =O14+P14+Q14+T14+U14+V14 -> 5951.9131 | X14: =L14-W14 -> -693.36439 | Y14: =N(Y13)+X14 -> -16944.829 | Z14: =IFERROR((U14+V14)/D14,0) -> 144.23845 | AA14: =IFERROR(T14/(R14/G14),0) -> 60.592438 | AC14: =D14*(1-Premissas!$F$23)*(1-Premissas!$F$24) -> 8.2472937 | AD14: =D14*(1-Premissas!$F$23)*Premissas!$F$24 -> 2.0618234 | AE14: =D14*Premissas!$F$23*(1-Premissas!$F$24) -> 2.7490979 | AF14: =D14*Premissas!$F$23*Premissas!$F$24 -> 0.68727447 | AG14: =AD14+IF(B14>12,INDEX($AD$6:$AD$29,B14-12)*Premissas!$F$22,0) -> 2.0618234 | AH14: =AF14+IF(B14>12,INDEX($AF$6:$AF$29,B14-12)*Premissas!$F$22,0) -> 0.68727447 | AI14: =IF(B14>12,(INDEX($AD$6:$AD$29,B14-12)+INDEX($AF$6:$AF$29,B14-12))*(1-Premissas!$F$22),0) -> 0 | AJ14: =H14+J14+AG14+AH14 -> 67.186954 | AK14: =IF(X14>0,B14,"")
B15: =B14+1 -> 10 | C15: =EDATE(Premissas!$C$7,B15-1) -> 46569 | D15: =Premissas!$F$19*(1+Premissas!$F$20)^(B15-1) -> 14.707674 | E15: =IFERROR(D15/Premissas!$F$25,0) -> 73.538368 | F15: =(N(H14)+N(J14))*Premissas!$F$21+AI15 -> 3.2218928 | G15: =H15+I15+J15+K15 -> 95.088419 | H15: =N(H14)*(1-Premissas!$F$21)+AC15 -> 54.736577 | I15: =SUM(INDEX($AG$6:$AG$29,MAX(1,B15-11)):INDEX($AG$6:$AG$29,B15)) -> 16.579738 | J15: =N(J14)*(1-Premissas!$F$21)+AE15 -> 18.245526 | K15: =SUM(INDEX($AH$6:$AH$29,MAX(1,B15-11)):INDEX($AH$6:$AH$29,B15)) -> 5.5265792 | L15: =H15*Premissas!$C$13+I15*Premissas!$F$13/12+J15*Premissas!$C$14+K15*Premissas!$F$14/12 -> 5977.6303 | M15: =L15*12 -> 71731.564 | N15: =IFERROR(L15/G15,0) -> 62.863915 | O15: =L15*Premissas!$C$30 -> 358.65782 | P15: =L15*Premissas!$C$28+AJ15*Premissas!$C$29 -> 246.41964 | Q15: =G15*Premissas!$C$31 -> 47.54421 | R15: =L15-O15-P15-Q15 -> 5325.0086 | S15: =IFERROR(R15/L15,0) -> 0.89082268 | T15: =SUMPRODUCT(Premissas!$C$42:$C$61,--(Premissas!$D$42:$D$61<=B15)) -> 3395 | U15: =Premissas!$C$34*(1+Premissas!$C$35)^(B15-1) -> 1957.1598 | V15: =D15*Premissas!$C$36*Premissas!$C$37 -> 88.246042 | W15: =O15+P15+Q15+T15+U15+V15 -> 6093.0275 | X15: =L15-W15 -> -115.39717 | Y15: =N(Y14)+X15 -> -17060.226 | Z15: =IFERROR((U15+V15)/D15,0) -> 139.07066 | AA15: =IFERROR(T15/(R15/G15),0) -> 60.624349 | AC15: =D15*(1-Premissas!$F$23)*(1-Premissas!$F$24) -> 8.8246042 | AD15: =D15*(1-Premissas!$F$23)*Premissas!$F$24 -> 2.2061511 | AE15: =D15*Premissas!$F$23*(1-Premissas!$F$24) -> 2.9415347 | AF15: =D15*Premissas!$F$23*Premissas!$F$24 -> 0.73538368 | AG15: =AD15+IF(B15>12,INDEX($AD$6:$AD$29,B15-12)*Premissas!$F$22,0) -> 2.2061511 | AH15: =AF15+IF(B15>12,INDEX($AF$6:$AF$29,B15-12)*Premissas!$F$22,0) -> 0.73538368 | AI15: =IF(B15>12,(INDEX($AD$6:$AD$29,B15-12)+INDEX($AF$6:$AF$29,B15-12))*(1-Premissas!$F$22),0) -> 0 | AJ15: =H15+J15+AG15+AH15 -> 75.923637 | AK15: =IF(X15>0,B15,"")
B16: =B15+1 -> 11 | C16: =EDATE(Premissas!$C$7,B16-1) -> 46600 | D16: =Premissas!$F$19*(1+Premissas!$F$20)^(B16-1) -> 15.737211 | E16: =IFERROR(D16/Premissas!$F$25,0) -> 78.686054 | F16: =(N(H15)+N(J15))*Premissas!$F$21+AI16 -> 3.6491051 | G16: =H16+I16+J16+K16 -> 107.17652 | H16: =N(H15)*(1-Premissas!$F$21)+AC16 -> 61.442074 | I16: =SUM(INDEX($AG$6:$AG$29,MAX(1,B16-11)):INDEX($AG$6:$AG$29,B16)) -> 18.940319 | J16: =N(J15)*(1-Premissas!$F$21)+AE16 -> 20.480691 | K16: =SUM(INDEX($AH$6:$AH$29,MAX(1,B16-11)):INDEX($AH$6:$AH$29,B16)) -> 6.3134397 | L16: =H16*Premissas!$C$13+I16*Premissas!$F$13/12+J16*Premissas!$C$14+K16*Premissas!$F$14/12 -> 6733.8578 | M16: =L16*12 -> 80806.293 | N16: =IFERROR(L16/G16,0) -> 62.829596 | O16: =L16*Premissas!$C$30 -> 404.03147 | P16: =L16*Premissas!$C$28+AJ16*Premissas!$C$29 -> 277.36942 | Q16: =G16*Premissas!$C$31 -> 53.588262 | R16: =L16-O16-P16-Q16 -> 5998.8686 | S16: =IFERROR(R16/L16,0) -> 0.8908517 | T16: =SUMPRODUCT(Premissas!$C$42:$C$61,--(Premissas!$D$42:$D$61<=B16)) -> 3395 | U16: =Premissas!$C$34*(1+Premissas!$C$35)^(B16-1) -> 2015.8746 | V16: =D16*Premissas!$C$36*Premissas!$C$37 -> 94.423265 | W16: =O16+P16+Q16+T16+U16+V16 -> 6240.287 | X16: =L16-W16 -> 493.57079 | Y16: =N(Y15)+X16 -> -16566.656 | Z16: =IFERROR((U16+V16)/D16,0) -> 134.09605 | AA16: =IFERROR(T16/(R16/G16),0) -> 60.655488 | AC16: =D16*(1-Premissas!$F$23)*(1-Premissas!$F$24) -> 9.4423265 | AD16: =D16*(1-Premissas!$F$23)*Premissas!$F$24 -> 2.3605816 | AE16: =D16*Premissas!$F$23*(1-Premissas!$F$24) -> 3.1474422 | AF16: =D16*Premissas!$F$23*Premissas!$F$24 -> 0.78686054 | AG16: =AD16+IF(B16>12,INDEX($AD$6:$AD$29,B16-12)*Premissas!$F$22,0) -> 2.3605816 | AH16: =AF16+IF(B16>12,INDEX($AF$6:$AF$29,B16-12)*Premissas!$F$22,0) -> 0.78686054 | AI16: =IF(B16>12,(INDEX($AD$6:$AD$29,B16-12)+INDEX($AF$6:$AF$29,B16-12))*(1-Premissas!$F$22),0) -> 0 | AJ16: =H16+J16+AG16+AH16 -> 85.070208 | AK16: =IF(X16>0,B16,"") -> 11
B17: =B16+1 -> 12 | C17: =EDATE(Premissas!$C$7,B17-1) -> 46631 | D17: =Premissas!$F$19*(1+Premissas!$F$20)^(B17-1) -> 16.838816 | E17: =IFERROR(D17/Premissas!$F$25,0) -> 84.194078 | F17: =(N(H16)+N(J16))*Premissas!$F$21+AI17 -> 4.0961383 | G17: =H17+I17+J17+K17 -> 119.9192 | H17: =N(H16)*(1-Premissas!$F$21)+AC17 -> 68.47326 | I17: =SUM(INDEX($AG$6:$AG$29,MAX(1,B17-11)):INDEX($AG$6:$AG$29,B17)) -> 21.466142 | J17: =N(J16)*(1-Premissas!$F$21)+AE17 -> 22.82442 | K17: =SUM(INDEX($AH$6:$AH$29,MAX(1,B17-11)):INDEX($AH$6:$AH$29,B17)) -> 7.1553805 | L17: =H17*Premissas!$C$13+I17*Premissas!$F$13/12+J17*Premissas!$C$14+K17*Premissas!$F$14/12 -> 7530.4908 | M17: =L17*12 -> 90365.889 | N17: =IFERROR(L17/G17,0) -> 62.796372 | O17: =L17*Premissas!$C$30 -> 451.82945 | P17: =L17*Premissas!$C$28+AJ17*Premissas!$C$29 -> 309.95324 | Q17: =G17*Premissas!$C$31 -> 59.959601 | R17: =L17-O17-P17-Q17 -> 6708.7485 | S17: =IFERROR(R17/L17,0) -> 0.89087799 | T17: =SUMPRODUCT(Premissas!$C$42:$C$61,--(Premissas!$D$42:$D$61<=B17)) -> 3395 | U17: =Premissas!$C$34*(1+Premissas!$C$35)^(B17-1) -> 2076.3508 | V17: =D17*Premissas!$C$36*Premissas!$C$37 -> 101.03289 | W17: =O17+P17+Q17+T17+U17+V17 -> 6394.126 | X17: =L17-W17 -> 1136.3648 | Y17: =N(Y16)+X17 -> -15430.291 | Z17: =IFERROR((U17+V17)/D17,0) -> 129.30741 | AA17: =IFERROR(T17/(R17/G17),0) -> 60.685788 | AC17: =D17*(1-Premissas!$F$23)*(1-Premissas!$F$24) -> 10.103289 | AD17: =D17*(1-Premissas!$F$23)*Premissas!$F$24 -> 2.5258223 | AE17: =D17*Premissas!$F$23*(1-Premissas!$F$24) -> 3.3677631 | AF17: =D17*Premissas!$F$23*Premissas!$F$24 -> 0.84194078 | AG17: =AD17+IF(B17>12,INDEX($AD$6:$AD$29,B17-12)*Premissas!$F$22,0) -> 2.5258223 | AH17: =AF17+IF(B17>12,INDEX($AF$6:$AF$29,B17-12)*Premissas!$F$22,0) -> 0.84194078 | AI17: =IF(B17>12,(INDEX($AD$6:$AD$29,B17-12)+INDEX($AF$6:$AF$29,B17-12))*(1-Premissas!$F$22),0) -> 0 | AJ17: =H17+J17+AG17+AH17 -> 94.665443 | AK17: =IF(X17>0,B17,"") -> 12
B18: =B17+1 -> 13 | C18: =EDATE(Premissas!$C$7,B18-1) -> 46661 | D18: =Premissas!$F$19*(1+Premissas!$F$20)^(B18-1) -> 18.017533 | E18: =IFERROR(D18/Premissas!$F$25,0) -> 90.087664 | F18: =(N(H17)+N(J17))*Premissas!$F$21+AI18 -> 5.124884 | G18: =H18+I18+J18+K18 -> 132.81185 | H18: =N(H17)*(1-Premissas!$F$21)+AC18 -> 75.860117 | I18: =SUM(INDEX($AG$6:$AG$29,MAX(1,B18-11)):INDEX($AG$6:$AG$29,B18)) -> 23.748771 | J18: =N(J17)*(1-Premissas!$F$21)+AE18 -> 25.286706 | K18: =SUM(INDEX($AH$6:$AH$29,MAX(1,B18-11)):INDEX($AH$6:$AH$29,B18)) -> 7.9162571 | L18: =H18*Premissas!$C$13+I18*Premissas!$F$13/12+J18*Premissas!$C$14+K18*Premissas!$F$14/12 -> 8340.4692 | M18: =L18*12 -> 100085.63 | N18: =IFERROR(L18/G18,0) -> 62.799134 | O18: =L18*Premissas!$C$30 -> 500.42815 | P18: =L18*Premissas!$C$28+AJ18*Premissas!$C$29 -> 343.75368 | Q18: =G18*Premissas!$C$31 -> 66.405925 | R18: =L18-O18-P18-Q18 -> 7429.8814 | S18: =IFERROR(R18/L18,0) -> 0.89082296 | T18: =SUMPRODUCT(Premissas!$C$42:$C$61,--(Premissas!$D$42:$D$61<=B18)) -> 3395 | U18: =Premissas!$C$34*(1+Premissas!$C$35)^(B18-1) -> 2138.6413 | V18: =D18*Premissas!$C$36*Premissas!$C$37 -> 108.1052 | W18: =O18+P18+Q18+T18+U18+V18 -> 6552.3343 | X18: =L18-W18 -> 1788.1349 | Y18: =N(Y17)+X18 -> -13642.156 | Z18: =IFERROR((U18+V18)/D18,0) -> 124.69779 | AA18: =IFERROR(T18/(R18/G18),0) -> 60.686868 | AC18: =D18*(1-Premissas!$F$23)*(1-Premissas!$F$24) -> 10.81052 | AD18: =D18*(1-Premissas!$F$23)*Premissas!$F$24 -> 2.7026299 | AE18: =D18*Premissas!$F$23*(1-Premissas!$F$24) -> 3.6035065 | AF18: =D18*Premissas!$F$23*Premissas!$F$24 -> 0.90087664 | AG18: =AD18+IF(B18>12,INDEX($AD$6:$AD$29,B18-12)*Premissas!$F$22,0) -> 3.4826299 | AH18: =AF18+IF(B18>12,INDEX($AF$6:$AF$29,B18-12)*Premissas!$F$22,0) -> 1.1608766 | AI18: =IF(B18>12,(INDEX($AD$6:$AD$29,B18-12)+INDEX($AF$6:$AF$29,B18-12))*(1-Premissas!$F$22),0) -> 0.56 | AJ18: =H18+J18+AG18+AH18 -> 105.79033 | AK18: =IF(X18>0,B18,"") -> 13
... B29: =B28+1 -> 24 | C29: =EDATE(Premissas!$C$7,B29-1) -> 46997 | D29: =Premissas!$F$19*(1+Premissas!$F$20)^(B29-1) -> 37.924239 | E29: =IFERROR(D29/Premissas!$F$25,0) -> 189.62119 | F29: =(N(H28)+N(J28))*Premissas!$F$21+AI29 -> 13.000512 | G29: =H29+I29+J29+K29 -> 338.01863 | H29: =N(H28)*(1-Premissas!$F$21)+AC29 -> 191.21512 | I29: =SUM(INDEX($AG$6:$AG$29,MAX(1,B29-11)):INDEX($AG$6:$AG$29,B29)) -> 62.298855 | J29: =N(J28)*(1-Premissas!$F$21)+AE29 -> 63.738372 | K29: =SUM(INDEX($AH$6:$AH$29,MAX(1,B29-11)):INDEX($AH$6:$AH$29,B29)) -> 20.766285 | L29: =H29*Premissas!$C$13+I29*Premissas!$F$13/12+J29*Premissas!$C$14+K29*Premissas!$F$14/12 -> 21200.282 | M29: =L29*12 -> 254403.38 | N29: =IFERROR(L29/G29,0) -> 62.719269 | O29: =L29*Premissas!$C$30 -> 1272.0169 | P29: =L29*Premissas!$C$28+AJ29*Premissas!$C$29 -> 871.72627 | Q29: =G29*Premissas!$C$31 -> 169.00932 | R29: =L29-O29-P29-Q29 -> 18887.529 | S29: =IFERROR(R29/L29,0) -> 0.89090935 | T29: =SUMPRODUCT(Premissas!$C$42:$C$61,--(Premissas!$D$42:$D$61<=B29)) -> 3395 | U29: =Premissas!$C$34*(1+Premissas!$C$35)^(B29-1) -> 2960.3798 | V29: =D29*Premissas!$C$36*Premissas!$C$37 -> 227.54543 | W29: =O29+P29+Q29+T29+U29+V29 -> 8895.6777 | X29: =L29-W29 -> 12304.604 | Y29: =N(Y28)+X29 -> 62578.916 | Z29: =IFERROR((U29+V29)/D29,0) -> 84.060361 | AA29: =IFERROR(T29/(R29/G29),0) -> 60.758252 | AC29: =D29*(1-Premissas!$F$23)*(1-Premissas!$F$24) -> 22.754543 | AD29: =D29*(1-Premissas!$F$23)*Premissas!$F$24 -> 5.6886358 | AE29: =D29*Premissas!$F$23*(1-Premissas!$F$24) -> 7.5848478 | AF29: =D29*Premissas!$F$23*Premissas!$F$24 -> 1.8962119 | AG29: =AD29+IF(B29>12,INDEX($AD$6:$AD$29,B29-12)*Premissas!$F$22,0) -> 7.3304204 | AH29: =AF29+IF(B29>12,INDEX($AF$6:$AF$29,B29-12)*Premissas!$F$22,0) -> 2.4434735 | AI29: =IF(B29>12,(INDEX($AD$6:$AD$29,B29-12)+INDEX($AF$6:$AF$29,B29-12))*(1-Premissas!$F$22),0) -> 1.1787171 | AJ29: =H29+J29+AG29+AH29 -> 264.72738 | AK29: =IF(X29>0,B29,"") -> 24
B30: TOTAL | D30: =SUM(D6:D29) -> 465.41337 | E30: =SUM(E6:E29) -> 2327.0668 | F30: =SUM(F6:F29) -> 127.39474 | L30: =SUM(L6:L29) -> 214730.24 | O30: =SUM(O6:O29) -> 12883.815 | P30: =SUM(P6:P29) -> 8845.5088 | Q30: =SUM(Q6:Q29) -> 1709.8181 | R30: =SUM(R6:R29) -> 191291.1 | T30: =SUM(T6:T29) -> 74280 | U30: =SUM(U6:U29) -> 51639.705 | V30: =SUM(V6:V29) -> 2792.4802 | W30: =SUM(W6:W29) -> 152151.33 | X30: =SUM(X6:X29) -> 62578.916 | AC30: =SUM(AC6:AC29) -> 279.24802 | AD30: =SUM(AD6:AD29) -> 69.812005 | AE30: =SUM(AE6:AE29) -> 93.082673 | AF30: =SUM(AF6:AF29) -> 23.270668 | AG30: =SUM(AG6:AG29) -> 83.764997 | AH30: =SUM(AH6:AH29) -> 27.921666 | AI30: =SUM(AI6:AI29) -> 10.017533 | AJ30: =SUM(AJ6:AJ29) -> 2714.1842

Sheet Fluxo de Caixa
B1: ⌂ Início | C1: ▦ Dashboard
B2: ="FLUXO DE CAIXA · CENÁRIO "&UPPER(Premissas!$C$9) -> FLUXO DE CAIXA · CENÁRIO REALISTA
B3: Quando o dinheiro ENTRA e SAI. O plano anual entra inteiro no mês da venda ou da renovação; a última coluna mostra quanto desse dinheiro ainda é receita dos meses seguintes (não gaste como se fosse lucro).
D4: ENTRADAS | G4: SAÍDAS | M4: SALDO | O4: PLANO ANUAL (COMPETÊNCIA)
B5: Nº | C5: MÊS | D5: ENTRADA MENSALIDADES | E5: ENTRADA PLANO ANUAL (À VISTA) | F5: TOTAL DE ENTRADAS | G5: (−) IMPOSTOS | H5: (−) GATEWAY | I5: (−) INFRA | J5: (−) CUSTOS FIXOS | K5: (−) MARKETING | L5: TOTAL DE SAÍDAS | M5: SALDO DO MÊS | N5: SALDO ACUMULADO EM CAIXA | O5: RECEITA ANUAL RECONHECIDA NO MÊS | P5: RECEITA ANUAL A RECONHECER (JÁ RECEBIDA)
B6: ='Projeção 24 meses'!B6 -> 1 | C6: ='Projeção 24 meses'!C6 -> 46296 | D6: ='Projeção 24 meses'!H6*Premissas!$C$13+'Projeção 24 meses'!J6*Premissas!$C$14 -> 418.56 | E6: ='Projeção 24 meses'!AG6*Premissas!$F$13+'Projeção 24 meses'!AH6*Premissas!$F$14 -> 1046.232 | F6: =D6+E6 -> 1464.792 | G6: =F6*Premissas!$C$30 -> 87.88752 | H6: =F6*Premissas!$C$28+'Projeção 24 meses'!AJ6*Premissas!$C$29 -> 55.18772 | I6: ='Projeção 24 meses'!Q6 -> 4 | J6: ='Projeção 24 meses'!T6 -> 2195 | K6: ='Projeção 24 meses'!U6+'Projeção 24 meses'!V6 -> 1548 | L6: =G6+H6+I6+J6+K6 -> 3890.0752 | M6: =F6-L6 -> -2425.2832 | N6: =IF('Projeção 24 meses'!B6=1,Premissas!$C$8,N(N5))+M6 -> -2425.2832 | O6: ='Projeção 24 meses'!I6*Premissas!$F$13/12+'Projeção 24 meses'!K6*Premissas!$F$14/12 -> 87.186 | P6: =N(P5)+E6-O6 -> 959.046
B7: ='Projeção 24 meses'!B7 -> 2 | C7: ='Projeção 24 meses'!C7 -> 46327 | D7: ='Projeção 24 meses'!H7*Premissas!$C$13+'Projeção 24 meses'!J7*Premissas!$C$14 -> 845.4912 | E7: ='Projeção 24 meses'!AG7*Premissas!$F$13+'Projeção 24 meses'!AH7*Premissas!$F$14 -> 1119.4682 | F7: =D7+E7 -> 1964.9594 | G7: =F7*Premissas!$C$30 -> 117.89757 | H7: =F7*Premissas!$C$28+'Projeção 24 meses'!AJ7*Premissas!$C$29 -> 75.94718 | I7: ='Projeção 24 meses'!Q7 -> 8.12 | J7: ='Projeção 24 meses'!T7 -> 2195 | K7: ='Projeção 24 meses'!U7+'Projeção 24 meses'!V7 -> 1596.36 | L7: =G7+H7+I7+J7+K7 -> 3993.3247 | M7: =F7-L7 -> -2028.3653 | N7: =IF('Projeção 24 meses'!B7=1,Premissas!$C$8,N(N6))+M7 -> -4453.6485 | O7: ='Projeção 24 meses'!I7*Premissas!$F$13/12+'Projeção 24 meses'!K7*Premissas!$F$14/12 -> 180.47502 | P7: =N(P6)+E7-O7 -> 1898.0392
B8: ='Projeção 24 meses'!B8 -> 3 | C8: ='Projeção 24 meses'!C8 -> 46357 | D8: ='Projeção 24 meses'!H8*Premissas!$C$13+'Projeção 24 meses'!J8*Premissas!$C$14 -> 1282.426 | E8: ='Projeção 24 meses'!AG8*Premissas!$F$13+'Projeção 24 meses'!AH8*Premissas!$F$14 -> 1197.831 | F8: =D8+E8 -> 2480.257 | G8: =F8*Premissas!$C$30 -> 148.81542 | H8: =F8*Premissas!$C$28+'Projeção 24 meses'!AJ8*Premissas!$C$29 -> 97.314987 | I8: ='Projeção 24 meses'!Q8 -> 12.3764 | J8: ='Projeção 24 meses'!T8 -> 2195 | K8: ='Projeção 24 meses'!U8+'Projeção 24 meses'!V8 -> 1646.3052 | L8: =G8+H8+I8+J8+K8 -> 4099.812 | M8: =F8-L8 -> -1619.555 | N8: =IF('Projeção 24 meses'!B8=1,Premissas!$C$8,N(N7))+M8 -> -6073.2036 | O8: ='Projeção 24 meses'!I8*Premissas!$F$13/12+'Projeção 24 meses'!K8*Premissas!$F$14/12 -> 280.29427 | P8: =N(P7)+E8-O8 -> 2815.576
B9: ='Projeção 24 meses'!B9 -> 4 | C9: ='Projeção 24 meses'!C9 -> 46388 | D9: ='Projeção 24 meses'!H9*Premissas!$C$13+'Projeção 24 meses'!J9*Premissas!$C$14 -> 1731.0587 | E9: ='Projeção 24 meses'!AG9*Premissas!$F$13+'Projeção 24 meses'!AH9*Premissas!$F$14 -> 1281.6792 | F9: =D9+E9 -> 3012.7379 | G9: =F9*Premissas!$C$30 -> 180.76427 | H9: =F9*Premissas!$C$28+'Projeção 24 meses'!AJ9*Premissas!$C$29 -> 119.37596 | I9: ='Projeção 24 meses'!Q9 -> 16.786348 | J9: ='Projeção 24 meses'!T9 -> 2195 | K9: ='Projeção 24 meses'!U9+'Projeção 24 meses'!V9 -> 1697.8926 | L9: =G9+H9+I9+J9+K9 -> 4209.8191 | M9: =F9-L9 -> -1197.0813 | N9: =IF('Projeção 24 meses'!B9=1,Premissas!$C$8,N(N8))+M9 -> -7270.2848 | O9: ='Projeção 24 meses'!I9*Premissas!$F$13/12+'Projeção 24 meses'!K9*Premissas!$F$14/12 -> 387.10087 | P9: =N(P8)+E9-O9 -> 3710.1543
B10: ='Projeção 24 meses'!B10 -> 5 | C10: ='Projeção 24 meses'!C10 -> 46419 | D10: ='Projeção 24 meses'!H10*Premissas!$C$13+'Projeção 24 meses'!J10*Premissas!$C$14 -> 2193.1525 | E10: ='Projeção 24 meses'!AG10*Premissas!$F$13+'Projeção 24 meses'!AH10*Premissas!$F$14 -> 1371.3967 | F10: =D10+E10 -> 3564.5493 | G10: =F10*Premissas!$C$30 -> 213.87296 | H10: =F10*Premissas!$C$28+'Projeção 24 meses'!AJ10*Premissas!$C$29 -> 142.21876 | I10: ='Projeção 24 meses'!Q10 -> 21.367812 | J10: ='Projeção 24 meses'!T10 -> 2195 | K10: ='Projeção 24 meses'!U10+'Projeção 24 meses'!V10 -> 1751.1814 | L10: =G10+H10+I10+J10+K10 -> 4323.641 | M10: =F10-L10 -> -759.0917 | N10: =IF('Projeção 24 meses'!B10=1,Premissas!$C$8,N(N9))+M10 -> -8029.3765 | O10: ='Projeção 24 meses'!I10*Premissas!$F$13/12+'Projeção 24 meses'!K10*Premissas!$F$14/12 -> 501.38393 | P10: =N(P9)+E10-O10 -> 4580.1671
B11: ='Projeção 24 meses'!B11 -> 6 | C11: ='Projeção 24 meses'!C11 -> 46447 | D11: ='Projeção 24 meses'!H11*Premissas!$C$13+'Projeção 24 meses'!J11*Premissas!$C$14 -> 2670.547 | E11: ='Projeção 24 meses'!AG11*Premissas!$F$13+'Projeção 24 meses'!AH11*Premissas!$F$14 -> 1467.3945 | F11: =D11+E11 -> 4137.9415 | G11: =F11*Premissas!$C$30 -> 248.27649 | H11: =F11*Premissas!$C$28+'Projeção 24 meses'!AJ11*Premissas!$C$29 -> 165.93624 | I11: ='Projeção 24 meses'!Q11 -> 26.139658 | J11: ='Projeção 24 meses'!T11 -> 2195 | K11: ='Projeção 24 meses'!U11+'Projeção 24 meses'!V11 -> 1806.2336 | L11: =G11+H11+I11+J11+K11 -> 4441.586 | M11: =F11-L11 -> -303.64452 | N11: =IF('Projeção 24 meses'!B11=1,Premissas!$C$8,N(N10))+M11 -> -8333.0211 | O11: ='Projeção 24 meses'!I11*Premissas!$F$13/12+'Projeção 24 meses'!K11*Premissas!$F$14/12 -> 623.66681 | P11: =N(P10)+E11-O11 -> 5423.8948
B12: ='Projeção 24 meses'!B12 -> 7 | C12: ='Projeção 24 meses'!C12 -> 46478 | D12: ='Projeção 24 meses'!H12*Premissas!$C$13+'Projeção 24 meses'!J12*Premissas!$C$14 -> 3165.1653 | E12: ='Projeção 24 meses'!AG12*Premissas!$F$13+'Projeção 24 meses'!AH12*Premissas!$F$14 -> 1570.1121 | F12: =D12+E12 -> 4735.2774 | G12: =F12*Premissas!$C$30 -> 284.11665 | H12: =F12*Premissas!$C$28+'Projeção 24 meses'!AJ12*Premissas!$C$29 -> 190.62582 | I12: ='Projeção 24 meses'!Q12 -> 31.121728 | J12: ='Projeção 24 meses'!T12 -> 3395 | K12: ='Projeção 24 meses'!U12+'Projeção 24 meses'!V12 -> 1863.1135 | L12: =G12+H12+I12+J12+K12 -> 5763.9777 | M12: =F12-L12 -> -1028.7003 | N12: =IF('Projeção 24 meses'!B12=1,Premissas!$C$8,N(N11))+M12 -> -9361.7213 | O12: ='Projeção 24 meses'!I12*Premissas!$F$13/12+'Projeção 24 meses'!K12*Premissas!$F$14/12 -> 754.50948 | P12: =N(P11)+E12-O12 -> 6239.4974
B13: ='Projeção 24 meses'!B13 -> 8 | C13: ='Projeção 24 meses'!C13 -> 46508 | D13: ='Projeção 24 meses'!H13*Premissas!$C$13+'Projeção 24 meses'!J13*Premissas!$C$14 -> 3679.0229 | E13: ='Projeção 24 meses'!AG13*Premissas!$F$13+'Projeção 24 meses'!AH13*Premissas!$F$14 -> 1680.02 | F13: =D13+E13 -> 5359.0429 | G13: =F13*Premissas!$C$30 -> 321.54257 | H13: =F13*Premissas!$C$28+'Projeção 24 meses'!AJ13*Premissas!$C$29 -> 216.38998 | I13: ='Projeção 24 meses'!Q13 -> 36.334929 | J13: ='Projeção 24 meses'!T13 -> 3395 | K13: ='Projeção 24 meses'!U13+'Projeção 24 meses'!V13 -> 1921.8883 | L13: =G13+H13+I13+J13+K13 -> 5891.1558 | M13: =F13-L13 -> -532.11289 | N13: =IF('Projeção 24 meses'!B13=1,Premissas!$C$8,N(N12))+M13 -> -9893.8342 | O13: ='Projeção 24 meses'!I13*Premissas!$F$13/12+'Projeção 24 meses'!K13*Premissas!$F$14/12 -> 894.51115 | P13: =N(P12)+E13-O13 -> 7025.0062
B14: ='Projeção 24 meses'!B14 -> 9 | C14: ='Projeção 24 meses'!C14 -> 46539 | D14: ='Projeção 24 meses'!H14*Premissas!$C$13+'Projeção 24 meses'!J14*Premissas!$C$14 -> 4214.2358 | E14: ='Projeção 24 meses'!AG14*Premissas!$F$13+'Projeção 24 meses'!AH14*Premissas!$F$14 -> 1797.6214 | F14: =D14+E14 -> 6011.8572 | G14: =F14*Premissas!$C$30 -> 360.71143 | H14: =F14*Premissas!$C$28+'Projeção 24 meses'!AJ14*Premissas!$C$29 -> 243.33661 | I14: ='Projeção 24 meses'!Q14 -> 41.801319 | J14: ='Projeção 24 meses'!T14 -> 3395 | K14: ='Projeção 24 meses'!U14+'Projeção 24 meses'!V14 -> 1982.6281 | L14: =G14+H14+I14+J14+K14 -> 6023.4774 | M14: =F14-L14 -> -11.62026 | N14: =IF('Projeção 24 meses'!B14=1,Premissas!$C$8,N(N13))+M14 -> -9905.4545 | O14: ='Projeção 24 meses'!I14*Premissas!$F$13/12+'Projeção 24 meses'!K14*Premissas!$F$14/12 -> 1044.3129 | P14: =N(P13)+E14-O14 -> 7778.3147
B15: ='Projeção 24 meses'!B15 -> 10 | C15: ='Projeção 24 meses'!C15 -> 46569 | D15: ='Projeção 24 meses'!H15*Premissas!$C$13+'Projeção 24 meses'!J15*Premissas!$C$14 -> 4773.0295 | E15: ='Projeção 24 meses'!AG15*Premissas!$F$13+'Projeção 24 meses'!AH15*Premissas!$F$14 -> 1923.4549 | F15: =D15+E15 -> 6696.4843 | G15: =F15*Premissas!$C$30 -> 401.78906 | H15: =F15*Premissas!$C$28+'Projeção 24 meses'!AJ15*Premissas!$C$29 -> 271.57953 | I15: ='Projeção 24 meses'!Q15 -> 47.54421 | J15: ='Projeção 24 meses'!T15 -> 3395 | K15: ='Projeção 24 meses'!U15+'Projeção 24 meses'!V15 -> 2045.4058 | L15: =G15+H15+I15+J15+K15 -> 6161.3186 | M15: =F15-L15 -> 535.16573 | N15: =IF('Projeção 24 meses'!B15=1,Premissas!$C$8,N(N14))+M15 -> -9370.2888 | O15: ='Projeção 24 meses'!I15*Premissas!$F$13/12+'Projeção 24 meses'!K15*Premissas!$F$14/12 -> 1204.6008 | P15: =N(P14)+E15-O15 -> 8497.1687
B16: ='Projeção 24 meses'!B16 -> 11 | C16: ='Projeção 24 meses'!C16 -> 46600 | D16: ='Projeção 24 meses'!H16*Premissas!$C$13+'Projeção 24 meses'!J16*Premissas!$C$14 -> 5357.7489 | E16: ='Projeção 24 meses'!AG16*Premissas!$F$13+'Projeção 24 meses'!AH16*Premissas!$F$14 -> 2058.0967 | F16: =D16+E16 -> 7415.8456 | G16: =F16*Premissas!$C$30 -> 444.95074 | H16: =F16*Premissas!$C$28+'Projeção 24 meses'!AJ16*Premissas!$C$29 -> 301.239 | I16: ='Projeção 24 meses'!Q16 -> 53.588262 | J16: ='Projeção 24 meses'!T16 -> 3395 | K16: ='Projeção 24 meses'!U16+'Projeção 24 meses'!V16 -> 2110.2978 | L16: =G16+H16+I16+J16+K16 -> 6305.0758 | M16: =F16-L16 -> 1110.7698 | N16: =IF('Projeção 24 meses'!B16=1,Premissas!$C$8,N(N15))+M16 -> -8259.519 | O16: ='Projeção 24 meses'!I16*Premissas!$F$13/12+'Projeção 24 meses'!K16*Premissas!$F$14/12 -> 1376.1089 | P16: =N(P15)+E16-O16 -> 9179.1565
B17: ='Projeção 24 meses'!B17 -> 12 | C17: ='Projeção 24 meses'!C17 -> 46631 | D17: ='Projeção 24 meses'!H17*Premissas!$C$13+'Projeção 24 meses'!J17*Premissas!$C$14 -> 5970.8683 | E17: ='Projeção 24 meses'!AG17*Premissas!$F$13+'Projeção 24 meses'!AH17*Premissas!$F$14 -> 2202.1635 | F17: =D17+E17 -> 8173.0317 | G17: =F17*Premissas!$C$30 -> 490.3819 | H17: =F17*Premissas!$C$28+'Projeção 24 meses'!AJ17*Premissas!$C$29 -> 332.44218 | I17: ='Projeção 24 meses'!Q17 -> 59.959601 | J17: ='Projeção 24 meses'!T17 -> 3395 | K17: ='Projeção 24 meses'!U17+'Projeção 24 meses'!V17 -> 2177.3837 | L17: =G17+H17+I17+J17+K17 -> 6455.1674 | M17: =F17-L17 -> 1717.8644 | N17: =IF('Projeção 24 meses'!B17=1,Premissas!$C$8,N(N16))+M17 -> -6541.6546 | O17: ='Projeção 24 meses'!I17*Premissas!$F$13/12+'Projeção 24 meses'!K17*Premissas!$F$14/12 -> 1559.6225 | P17: =N(P16)+E17-O17 -> 9821.6975
... B29: ='Projeção 24 meses'!B29 -> 24 | C29: ='Projeção 24 meses'!C29 -> 46997 | D29: ='Projeção 24 meses'!H29*Premissas!$C$13+'Projeção 24 meses'!J29*Premissas!$C$14 -> 16673.958 | E29: ='Projeção 24 meses'!AG29*Premissas!$F$13+'Projeção 24 meses'!AH29*Premissas!$F$14 -> 6391.1003 | F29: =D29+E29 -> 23065.059 | G29: =F29*Premissas!$C$30 -> 1383.9035 | H29: =F29*Premissas!$C$28+'Projeção 24 meses'!AJ29*Premissas!$C$29 -> 936.99347 | I29: ='Projeção 24 meses'!Q29 -> 169.00932 | J29: ='Projeção 24 meses'!T29 -> 3395 | K29: ='Projeção 24 meses'!U29+'Projeção 24 meses'!V29 -> 3187.9252 | L29: =G29+H29+I29+J29+K29 -> 9072.8315 | M29: =F29-L29 -> 13992.227 | N29: =IF('Projeção 24 meses'!B29=1,Premissas!$C$8,N(N28))+M29 -> 88375.441 | O29: ='Projeção 24 meses'!I29*Premissas!$F$13/12+'Projeção 24 meses'!K29*Premissas!$F$14/12 -> 4526.3233 | P29: =N(P28)+E29-O29 -> 28504.448
B30: TOTAL | D30: =SUM(D6:D29) -> 170203.34 | E30: =SUM(E6:E29) -> 73031.35 | F30: =SUM(F6:F29) -> 243234.69 | G30: =SUM(G6:G29) -> 14594.081 | H30: =SUM(H6:H29) -> 9843.1644 | I30: =SUM(I6:I29) -> 1709.8181 | J30: =SUM(J6:J29) -> 74280 | K30: =SUM(K6:K29) -> 54432.186 | ... M30: =SUM(M6:M29) -> 88375.441 | O30: =SUM(O6:O29) -> 44526.902
B32: RESUMO DO CAIXA
B33: Caixa no fim do mês 24 | G33: =N29 -> 88375.441
B34: Menor saldo acumulado (necessidade máxima de capital) | G34: =MIN(N6:N29) -> -9905.4545
B35: Mês do menor saldo | G35: =INDEX(C6:C29,MATCH(MIN(N6:N29),N6:N29,0)) -> 46539
B36: Total recebido à vista em planos anuais (24 meses) | G36: =E30 -> 73031.35
B37: Receita anual já recebida e ainda a reconhecer no mês 24 | G37: =P29 -> 28504.448

Sheet Unit Economics
B1: ⌂ Início | C1: ▦ Dashboard
B2: ="UNIT ECONOMICS · CENÁRIO "&UPPER(Premissas!$C$9) -> UNIT ECONOMICS · CENÁRIO REALISTA
B3: Quanto cada cliente deixa, quanto custa para conquistá-lo e em quantos meses ele se paga. LTV = ticket × margem ÷ churn.
B5: CAC — CUSTO PARA CONQUISTAR UM CLIENTE
B6: Investimento em aquisição em 24 meses (anúncios + comissões) | C6: ='Projeção 24 meses'!$U$30+'Projeção 24 meses'!$V$30 -> 54432.186
B7: Novos clientes em 24 meses | C7: ='Projeção 24 meses'!$D$30 -> 465.41337
B8: CAC médio dos 24 meses | C8: =IFERROR(C6/C7,0) -> 116.9545
B9: CAC no mês 1 | C9: ='Projeção 24 meses'!$Z$6 -> 193.5
B10: CAC no mês 24 | C10: ='Projeção 24 meses'!$Z$29 -> 84.060361
B12: RETORNO POR CLIENTE — POR PLANO
B13: PLANO / COBRANÇA | C13: PESO NO MIX | D13: RECEITA POR MÊS | E13: CUSTO VARIÁVEL POR MÊS | F13: MARGEM POR MÊS | G13: MARGEM % | H13: CHURN MENSAL (EQUIV.) | I13: VIDA MÉDIA | J13: LTV | K13: LTV / CAC | L13: PAYBACK DO CAC
B14: Essencial mensal | C14: =(1-Premissas!$F$23)*(1-Premissas!$F$24) -> 0.6 | D14: =Premissas!$C$13 -> 57.9 | E14: =D14*(Premissas!$C$30+Premissas!$C$28)+1*Premissas!$C$29+Premissas!$C$31 -> 6.4905 | F14: =D14-E14 -> 51.4095 | G14: =IFERROR(F14/D14,0) -> 0.88790155 | H14: =Premissas!$F$21 -> 0.05 | I14: =IFERROR(1/H14,0) -> 20 | J14: =IFERROR(D14*G14/H14,0) -> 1028.19 | K14: =IFERROR(J14/$C$8,0) -> 8.7913679 | L14: =IFERROR($C$8/F14,0) -> 2.2749588
B15: Essencial anual | C15: =(1-Premissas!$F$23)*Premissas!$F$24 -> 0.15 | D15: =Premissas!$F$13/12 -> 49.215 | E15: =D15*(Premissas!$C$30+Premissas!$C$28)+1/12*Premissas!$C$29+Premissas!$C$31 -> 5.2162583 | F15: =D15-E15 -> 43.998742 | G15: =IFERROR(F15/D15,0) -> 0.8940108 | H15: =(1-Premissas!$F$22)/12 -> 0.029166667 | I15: =IFERROR(1/H15,0) -> 34.285714 | J15: =IFERROR(D15*G15/H15,0) -> 1508.5283 | K15: =IFERROR(J15/$C$8,0) -> 12.898421 | L15: =IFERROR($C$8/F15,0) -> 2.6581327
B16: Pro mensal | C16: =Premissas!$F$23*(1-Premissas!$F$24) -> 0.2 | D16: =Premissas!$C$14 -> 87.9 | E16: =D16*(Premissas!$C$30+Premissas!$C$28)+1*Premissas!$C$29+Premissas!$C$31 -> 9.3405 | F16: =D16-E16 -> 78.5595 | G16: =IFERROR(F16/D16,0) -> 0.8937372 | H16: =Premissas!$F$21 -> 0.05 | I16: =IFERROR(1/H16,0) -> 20 | J16: =IFERROR(D16*G16/H16,0) -> 1571.19 | K16: =IFERROR(J16/$C$8,0) -> 13.434199 | L16: =IFERROR($C$8/F16,0) -> 1.4887378
B17: Pro anual | C17: =Premissas!$F$23*Premissas!$F$24 -> 0.05 | D17: =Premissas!$F$14/12 -> 70.32 | E17: =D17*(Premissas!$C$30+Premissas!$C$28)+1/12*Premissas!$C$29+Premissas!$C$31 -> 7.2212333 | F17: =D17-E17 -> 63.098767 | G17: =IFERROR(F17/D17,0) -> 0.89730897 | H17: =(1-Premissas!$F$22)/12 -> 0.029166667 | I17: =IFERROR(1/H17,0) -> 34.285714 | J17: =IFERROR(D17*G17/H17,0) -> 2163.3863 | K17: =IFERROR(J17/$C$8,0) -> 18.497675 | L17: =IFERROR($C$8/F17,0) -> 1.8535148
B18: MÉDIA PONDERADA (mix em uso) | C18: =SUM(C14:C17) -> 1 | D18: =SUMPRODUCT($C$14:$C$17,D14:D17) -> 63.21825 | E18: =SUMPRODUCT($C$14:$C$17,E14:E17) -> 6.9059004 | F18: =SUMPRODUCT($C$14:$C$17,F14:F17) -> 56.31235 | G18: =IFERROR(F18/D18,0) -> 0.89076097 | H18: =SUMPRODUCT($C$14:$C$17,H14:H17) -> 0.045833333 | I18: =IFERROR(1/H18,0) -> 21.818182 | J18: =IFERROR(D18*G18/H18,0) -> 1228.6331 | K18: =IFERROR(J18/$C$8,0) -> 10.505223 | L18: =IFERROR($C$8/F18,0) -> 2.0768889
B19: =IF(K18>=3,"✔ Saudável: cada cliente devolve 3x ou mais o que custou para conquistar.",IF(K18>=1,"⚠ Atenção: LTV/CAC entre 1x e 3x — o cliente se paga, mas sobra pouco.","✖ Cada cliente custa mais do que devolve. Reveja CAC, preço ou churn.")) -> ✔ Saudável: cada cliente devolve 3x ou mais o que custou para conquistar.
B20: Plano anual: churn equivalente = (1 − renovação) ÷ 12. Referência de mercado SaaS: LTV/CAC ≥ 3x e payback ≤ 12 meses.
B22: VISÃO REAL DA PROJEÇÃO (24 MESES)
B23: Ticket médio real (ARPU = MRR ÷ clientes ativos) | C23: =IFERROR('Projeção 24 meses'!$L$30/SUM('Projeção 24 meses'!$G$6:$G$29),0) -> 62.793301
B24: Margem bruta real % | C24: =IFERROR('Projeção 24 meses'!$R$30/'Projeção 24 meses'!$L$30,0) -> 0.89084378
B25: Churn efetivo médio (cancelados ÷ ativos do mês anterior) | C25: =IFERROR('Projeção 24 meses'!$F$30/(SUM('Projeção 24 meses'!$G$6:$G$29)-'Projeção 24 meses'!$G$29),0) -> 0.041340217 | D25: No início quase ninguém cancela (anuais só saem no mês 13), por isso o churn efetivo fica abaixo do churn digitado.
B26: LTV (ticket × margem ÷ churn efetivo) | C26: =IFERROR(C23*C24/C25,0) -> 1353.1381
B27: LTV / CAC | C27: =IFERROR(C26/$C$8,0) -> 11.569783
B28: Payback do CAC (meses) | C28: =IFERROR($C$8/(C23*C24),0) -> 2.0907497
B30: PONTO DE EQUILÍBRIO
B31: Margem média por cliente/mês (mix em uso) | C31: =F18 -> 56.31235
B32: Custos fixos no mês 24 | C32: ='Projeção 24 meses'!$T$29 -> 3395
B33: Clientes necessários para cobrir os custos fixos | C33: =IFERROR(ROUNDUP(C32/C31,0),0) -> 61 | D33: Mesmo número que a coluna CLIENTES P/ EQUILÍBRIO da Projeção (mês a mês).
B34: Clientes necessários para cobrir fixos + marketing do mês 24 | C34: =IFERROR(ROUNDUP((C32+'Projeção 24 meses'!$U$29+'Projeção 24 meses'!$V$29)/C31,0),0) -> 117
B35: Clientes ativos no mês 24 | C35: ='Projeção 24 meses'!$G$29 -> 338.01863
B36: Primeiro mês com lucro líquido positivo | C36: =IF(COUNT('Projeção 24 meses'!$AK$6:$AK$29)=0,"Não atinge em 24 meses",INDEX('Projeção 24 meses'!$C$6:$C$29,MIN('Projeção 24 meses'!$AK$6:$AK$29))) -> 46600

Sheet Cenários
B1: ⌂ Início | C1: ▦ Dashboard
B2: CENÁRIOS · PESSIMISTA × REALISTA × OTIMISTA
B3: Os três cenários calculados ao mesmo tempo. As premissas de cada um ficam na aba Premissas (tabela PREMISSAS DE VENDA POR CENÁRIO).
B5: INDICADOR | C5: PESSIMISTA | D5: REALISTA | E5: OTIMISTA
B6: Clientes ativos — mês 12 | C6: ='Motor Cenários'!$G$17 -> 40.305359 | D6: ='Motor Cenários'!$BD$17 -> 119.9192 | E6: ='Motor Cenários'!$DA$17 -> 332.74845
B7: Clientes ativos — mês 24 | C7: ='Motor Cenários'!$G$29 -> 73.035963 | D7: ='Motor Cenários'!$BD$29 -> 338.01863 | E7: ='Motor Cenários'!$DA$29 -> 1538.7836
B8: MRR — mês 12 | C8: ='Motor Cenários'!$L$17 -> 2458.177 | D8: ='Motor Cenários'!$BI$17 -> 7530.4908 | E8: ='Motor Cenários'!$DF$17 -> 21478.715
B9: MRR — mês 24 | C9: ='Motor Cenários'!$L$29 -> 4447.9118 | D9: ='Motor Cenários'!$BI$29 -> 21200.282 | E9: ='Motor Cenários'!$DF$29 -> 99235.94
B10: ARR — mês 24 | C10: ='Motor Cenários'!$M$29 -> 53374.942 | D10: ='Motor Cenários'!$BJ$29 -> 254403.38 | E10: ='Motor Cenários'!$DG$29 -> 1190831.3
B11: Ticket médio (ARPU) — mês 24 | C11: ='Motor Cenários'!$N$29 -> 60.900297 | D11: ='Motor Cenários'!$BK$29 -> 62.719269 | E11: ='Motor Cenários'!$DH$29 -> 64.489861
B12: Lucro líquido — mês 24 | C12: ='Motor Cenários'!$X$29 -> -2444.8569 | D12: ='Motor Cenários'!$BU$29 -> 12304.604 | E12: ='Motor Cenários'!$DR$29 -> 80923.91
B13: Lucro acumulado em 24 meses | C13: ='Motor Cenários'!$Y$29 -> -74078.754 | D13: ='Motor Cenários'!$BV$29 -> 62578.916 | E13: ='Motor Cenários'!$DS$29 -> 556251.74
B14: Caixa no fim do mês 24 | C14: ='Motor Cenários'!$AU$29 -> -71046.299 | D14: ='Motor Cenários'!$CR$29 -> 88375.441 | E14: ='Motor Cenários'!$EO$29 -> 734161.51
B15: Menor saldo de caixa (capital necessário) | C15: =MIN('Motor Cenários'!$AU$6:$AU$29) -> -71046.299 | D15: =MIN('Motor Cenários'!$CR$6:$CR$29) -> -9905.4545 | E15: =MIN('Motor Cenários'!$EO$6:$EO$29) -> -383.75148
B16: Primeiro mês com lucro | C16: =IF(COUNT('Motor Cenários'!$AJ$6:$AJ$29)=0,"Não atinge",INDEX('Motor Cenários'!$C$6:$C$29,MIN('Motor Cenários'!$AJ$6:$AJ$29))) -> Não atinge | D16: =IF(COUNT('Motor Cenários'!$CG$6:$CG$29)=0,"Não atinge",INDEX('Motor Cenários'!$AZ$6:$AZ$29,MIN('Motor Cenários'!$CG$6:$CG$29))) -> 46600 | E16: =IF(COUNT('Motor Cenários'!$ED$6:$ED$29)=0,"Não atinge",INDEX('Motor Cenários'!$CW$6:$CW$29,MIN('Motor Cenários'!$ED$6:$ED$29))) -> 46388
B17: CAC médio (24 meses) | C17: =IFERROR(('Motor Cenários'!$U$30+'Motor Cenários'!$V$30)/'Motor Cenários'!$D$30,0) -> 381 | D17: =IFERROR(('Motor Cenários'!$BR$30+'Motor Cenários'!$BS$30)/'Motor Cenários'!$BA$30,0) -> 116.9545 | E17: =IFERROR(('Motor Cenários'!$DO$30+'Motor Cenários'!$DP$30)/'Motor Cenários'!$CX$30,0) -> 35.136643
B18: LTV (ticket × margem ÷ churn equivalente) | C18: =IFERROR('Motor Cenários'!$R$29/'Motor Cenários'!$G$29/(Premissas!$C$21*(1-Premissas!$C$24)+(1-Premissas!$C$22)/12*Premissas!$C$24),0) -> 711.47868 | D18: =IFERROR('Motor Cenários'!$BO$29/'Motor Cenários'!$BD$29/(Premissas!$D$21*(1-Premissas!$D$24)+(1-Premissas!$D$22)/12*Premissas!$D$24),0) -> 1219.1386 | E18: =IFERROR('Motor Cenários'!$DL$29/'Motor Cenários'!$DA$29/(Premissas!$E$21*(1-Premissas!$E$24)+(1-Premissas!$E$22)/12*Premissas!$E$24),0) -> 2212.012
B19: LTV / CAC | C19: =IFERROR(C18/C17,0) -> 1.8673981 | D19: =IFERROR(D18/D17,0) -> 10.424042 | E19: =IFERROR(E18/E17,0) -> 62.954563
B20: LTV aqui usa a margem por cliente do mês 24 e o churn equivalente do mix (mensal + anual).
B21: =IF(ABS(INDEX(C9:E9,MATCH(Premissas!$C$9,$C$5:$E$5,0))-'Projeção 24 meses'!$L$29)<0.01,"✔ Conferência: o cenário em uso bate com a aba Projeção 24 meses.","✖ Conferência: diferença entre Motor e Projeção.") -> ✔ Conferência: o cenário em uso bate com a aba Projeção 24 meses.
B54: DADOS DOS GRÁFICOS
B55: MÊS | C55: MRR PESSIMISTA | D55: MRR REALISTA | E55: MRR OTIMISTA | F55: CLIENTES PESS. | G55: CLIENTES REAL. | H55: CLIENTES OTIM. | I55: CAIXA PESS. | J55: CAIXA REAL. | K55: CAIXA OTIM.
B56: ='Motor Cenários'!$AZ$6 -> 46296 | C56: ='Motor Cenários'!$L$6 -> 245.5923 | D56: ='Motor Cenários'!$BI$6 -> 505.746 | E56: ='Motor Cenários'!$DF$6 -> 972.90787 | F56: ='Motor Cenários'!$G$6 -> 4 | G56: ='Motor Cenários'!$BD$6 -> 8 | H56: ='Motor Cenários'!$DA$6 -> 15 | I56: ='Motor Cenários'!$AU$6 -> -3292.1188 | J56: ='Motor Cenários'!$CR$6 -> -2425.2832 | K56: ='Motor Cenários'!$EO$6 -> -383.75148
