Workbook

Sheet Como usar
A1: Controle de Vendas da Barraca
A2: Planilha grátis do Sai aê · pedido, cozinha e senha para feira, food truck e lanchonete
A5: COMO USAR
A6: 1. Produtos | B6: Cadastre o que você vende, com o preço de venda e quanto custa para fazer cada um.
A7: 2. Despesas | B7: Confira as taxas da sua maquininha e lance as despesas do mês (taxa da feira, gás, embalagem...).
A8: 3. Vendas | B8: A cada venda, lance a data, o produto, a quantidade e a forma de pagamento. O resto a planilha calcula.
A9: 4. Resumo | B9: Escolha o mês e veja quanto vendeu, quanto sobrou de lucro e o que mais vende.
A11: CORES
A12: Amarelo-claro | B12: Você preenche.
A13: Branco | B13: A planilha calcula sozinha. Não precisa mexer.
A15: MÊS DO RESUMO
A16: Resumo | B16: Abre no mês atual. Para ver outro mês, digite qualquer data dele na célula amarelo-clara.
A18: Cansou de anotar? | B18: No Sai aê, cada venda lançada no caixa já entra no relatório do dia, sem digitar de novo.

Sheet Resumo
A1: Resumo do mês
A2: Escolha o mês na célula amarelo-clara. Todo o resto é automático.
A5: Mês | B5: =TODAY() -> 46291 | C5: =DATE(YEAR(B5),MONTH(B5),1) -> 46266 | D5: =EDATE(C5,1) -> 46296 | E5: ← início e fim do mês (automático)
A7: Resultado do mês | B7: Valor | D7: Forma de pagamento | E7: Vendas | F7: % do mês | I7: Dia | J7: Vendas
A8: Vendas | B8: =SUMIFS(Vendas!$F$5:$F$1004,Vendas!$A$5:$A$1004,">="&$C$5,Vendas!$A$5:$A$1004,"<"&$D$5) -> 0 | D8: Pix | E8: =SUMIFS(Vendas!$F$5:$F$1004,Vendas!$D$5:$D$1004,D8,Vendas!$A$5:$A$1004,">="&$C$5,Vendas!$A$5:$A$1004,"<"&$D$5) -> 0 | F8: =IF($B$8=0,0,E8/$B$8) -> 0 | I8: =IF(MONTH($C$5+0)=MONTH($C$5),$C$5+0,"") -> 46266 | J8: =IF(I8="",0,SUMIFS(Vendas!$F$5:$F$1004,Vendas!$A$5:$A$1004,I8)) -> 0
A9: (−) Custo dos produtos | B9: =SUMIFS(Vendas!$G$5:$G$1004,Vendas!$A$5:$A$1004,">="&$C$5,Vendas!$A$5:$A$1004,"<"&$D$5) -> 0 | D9: Dinheiro | E9: =SUMIFS(Vendas!$F$5:$F$1004,Vendas!$D$5:$D$1004,D9,Vendas!$A$5:$A$1004,">="&$C$5,Vendas!$A$5:$A$1004,"<"&$D$5) -> 0 | F9: =IF($B$8=0,0,E9/$B$8) -> 0 | I9: =IF(MONTH($C$5+1)=MONTH($C$5),$C$5+1,"") -> 46267 | J9: =IF(I9="",0,SUMIFS(Vendas!$F$5:$F$1004,Vendas!$A$5:$A$1004,I9)) -> 0
A10: (−) Taxas da maquininha | B10: =SUMIFS(Vendas!$H$5:$H$1004,Vendas!$A$5:$A$1004,">="&$C$5,Vendas!$A$5:$A$1004,"<"&$D$5) -> 0 | D10: Débito | E10: =SUMIFS(Vendas!$F$5:$F$1004,Vendas!$D$5:$D$1004,D10,Vendas!$A$5:$A$1004,">="&$C$5,Vendas!$A$5:$A$1004,"<"&$D$5) -> 0 | F10: =IF($B$8=0,0,E10/$B$8) -> 0 | I10: =IF(MONTH($C$5+2)=MONTH($C$5),$C$5+2,"") -> 46268 | J10: =IF(I10="",0,SUMIFS(Vendas!$F$5:$F$1004,Vendas!$A$5:$A$1004,I10)) -> 0
A11: Lucro bruto | B11: =B8-B9-B10 -> 0 | D11: Crédito | E11: =SUMIFS(Vendas!$F$5:$F$1004,Vendas!$D$5:$D$1004,D11,Vendas!$A$5:$A$1004,">="&$C$5,Vendas!$A$5:$A$1004,"<"&$D$5) -> 0 | F11: =IF($B$8=0,0,E11/$B$8) -> 0 | I11: =IF(MONTH($C$5+3)=MONTH($C$5),$C$5+3,"") -> 46269 | J11: =IF(I11="",0,SUMIFS(Vendas!$F$5:$F$1004,Vendas!$A$5:$A$1004,I11)) -> 0
A12: (−) Despesas do mês | B12: =SUMIFS(Despesas!$D$13:$D$212,Despesas!$A$13:$A$212,">="&$C$5,Despesas!$A$13:$A$212,"<"&$D$5) -> 0 | I12: =IF(MONTH($C$5+4)=MONTH($C$5),$C$5+4,"") -> 46270 | J12: =IF(I12="",0,SUMIFS(Vendas!$F$5:$F$1004,Vendas!$A$5:$A$1004,I12)) -> 0
A13: Lucro líquido do mês | B13: =B11-B12 -> 0 | I13: =IF(MONTH($C$5+5)=MONTH($C$5),$C$5+5,"") -> 46271 | J13: =IF(I13="",0,SUMIFS(Vendas!$F$5:$F$1004,Vendas!$A$5:$A$1004,I13)) -> 0
A14: Margem líquida | B14: =IF(B8=0,0,B13/B8) -> 0 | I14: =IF(MONTH($C$5+6)=MONTH($C$5),$C$5+6,"") -> 46272 | J14: =IF(I14="",0,SUMIFS(Vendas!$F$5:$F$1004,Vendas!$A$5:$A$1004,I14)) -> 0
A15: Itens vendidos | B15: =SUMIFS(Vendas!$C$5:$C$1004,Vendas!$A$5:$A$1004,">="&$C$5,Vendas!$A$5:$A$1004,"<"&$D$5) -> 0 | I15: =IF(MONTH($C$5+7)=MONTH($C$5),$C$5+7,"") -> 46273 | J15: =IF(I15="",0,SUMIFS(Vendas!$F$5:$F$1004,Vendas!$A$5:$A$1004,I15)) -> 0
A16: Dias com venda | B16: =COUNTIF($J$8:$J$38,">0") -> 0 | I16: =IF(MONTH($C$5+8)=MONTH($C$5),$C$5+8,"") -> 46274 | J16: =IF(I16="",0,SUMIFS(Vendas!$F$5:$F$1004,Vendas!$A$5:$A$1004,I16)) -> 0
A17: Média de vendas por dia | B17: =IF(B16=0,0,B8/B16) -> 0 | I17: =IF(MONTH($C$5+9)=MONTH($C$5),$C$5+9,"") -> 46275 | J17: =IF(I17="",0,SUMIFS(Vendas!$F$5:$F$1004,Vendas!$A$5:$A$1004,I17)) -> 0
I18: =IF(MONTH($C$5+10)=MONTH($C$5),$C$5+10,"") -> 46276 | J18: =IF(I18="",0,SUMIFS(Vendas!$F$5:$F$1004,Vendas!$A$5:$A$1004,I18)) -> 0
A19: POR PRODUTO NO MÊS | I19: =IF(MONTH($C$5+11)=MONTH($C$5),$C$5+11,"") -> 46277 | J19: =IF(I19="",0,SUMIFS(Vendas!$F$5:$F$1004,Vendas!$A$5:$A$1004,I19)) -> 0
A20: Produto | B20: Qtd vendida | C20: Vendas | D20: Lucro | E20: % das vendas | F20: Lucro por unidade | I20: =IF(MONTH($C$5+12)=MONTH($C$5),$C$5+12,"") -> 46278 | J20: =IF(I20="",0,SUMIFS(Vendas!$F$5:$F$1004,Vendas!$A$5:$A$1004,I20)) -> 0
A21: =IF(Produtos!A5="","",Produtos!A5) | B21: =IF(A21="","",SUMIFS(Vendas!$C$5:$C$1004,Vendas!$B$5:$B$1004,A21,Vendas!$A$5:$A$1004,">="&$C$5,Vendas!$A$5:$A$1004,"<"&$D$5)) | C21: =IF(A21="","",SUMIFS(Vendas!$F$5:$F$1004,Vendas!$B$5:$B$1004,A21,Vendas!$A$5:$A$1004,">="&$C$5,Vendas!$A$5:$A$1004,"<"&$D$5)) | D21: =IF(A21="","",SUMIFS(Vendas!$I$5:$I$1004,Vendas!$B$5:$B$1004,A21,Vendas!$A$5:$A$1004,">="&$C$5,Vendas!$A$5:$A$1004,"<"&$D$5)) | E21: =IF(OR(A21="",$B$8=0),"",C21/$B$8) | F21: =IF(A21="","",Produtos!E5) | I21: =IF(MONTH($C$5+13)=MONTH($C$5),$C$5+13,"") -> 46279 | J21: =IF(I21="",0,SUMIFS(Vendas!$F$5:$F$1004,Vendas!$A$5:$A$1004,I21)) -> 0
A22: =IF(Produtos!A6="","",Produtos!A6) | B22: =IF(A22="","",SUMIFS(Vendas!$C$5:$C$1004,Vendas!$B$5:$B$1004,A22,Vendas!$A$5:$A$1004,">="&$C$5,Vendas!$A$5:$A$1004,"<"&$D$5)) | C22: =IF(A22="","",SUMIFS(Vendas!$F$5:$F$1004,Vendas!$B$5:$B$1004,A22,Vendas!$A$5:$A$1004,">="&$C$5,Vendas!$A$5:$A$1004,"<"&$D$5)) | D22: =IF(A22="","",SUMIFS(Vendas!$I$5:$I$1004,Vendas!$B$5:$B$1004,A22,Vendas!$A$5:$A$1004,">="&$C$5,Vendas!$A$5:$A$1004,"<"&$D$5)) | E22: =IF(OR(A22="",$B$8=0),"",C22/$B$8) | F22: =IF(A22="","",Produtos!E6) | I22: =IF(MONTH($C$5+14)=MONTH($C$5),$C$5+14,"") -> 46280 | J22: =IF(I22="",0,SUMIFS(Vendas!$F$5:$F$1004,Vendas!$A$5:$A$1004,I22)) -> 0
A23: =IF(Produtos!A7="","",Produtos!A7) | B23: =IF(A23="","",SUMIFS(Vendas!$C$5:$C$1004,Vendas!$B$5:$B$1004,A23,Vendas!$A$5:$A$1004,">="&$C$5,Vendas!$A$5:$A$1004,"<"&$D$5)) | C23: =IF(A23="","",SUMIFS(Vendas!$F$5:$F$1004,Vendas!$B$5:$B$1004,A23,Vendas!$A$5:$A$1004,">="&$C$5,Vendas!$A$5:$A$1004,"<"&$D$5)) | D23: =IF(A23="","",SUMIFS(Vendas!$I$5:$I$1004,Vendas!$B$5:$B$1004,A23,Vendas!$A$5:$A$1004,">="&$C$5,Vendas!$A$5:$A$1004,"<"&$D$5)) | E23: =IF(OR(A23="",$B$8=0),"",C23/$B$8) | F23: =IF(A23="","",Produtos!E7) | I23: =IF(MONTH($C$5+15)=MONTH($C$5),$C$5+15,"") -> 46281 | J23: =IF(I23="",0,SUMIFS(Vendas!$F$5:$F$1004,Vendas!$A$5:$A$1004,I23)) -> 0
A24: =IF(Produtos!A8="","",Produtos!A8) | B24: =IF(A24="","",SUMIFS(Vendas!$C$5:$C$1004,Vendas!$B$5:$B$1004,A24,Vendas!$A$5:$A$1004,">="&$C$5,Vendas!$A$5:$A$1004,"<"&$D$5)) | C24: =IF(A24="","",SUMIFS(Vendas!$F$5:$F$1004,Vendas!$B$5:$B$1004,A24,Vendas!$A$5:$A$1004,">="&$C$5,Vendas!$A$5:$A$1004,"<"&$D$5)) | D24: =IF(A24="","",SUMIFS(Vendas!$I$5:$I$1004,Vendas!$B$5:$B$1004,A24,Vendas!$A$5:$A$1004,">="&$C$5,Vendas!$A$5:$A$1004,"<"&$D$5)) | E24: =IF(OR(A24="",$B$8=0),"",C24/$B$8) | F24: =IF(A24="","",Produtos!E8) | I24: =IF(MONTH($C$5+16)=MONTH($C$5),$C$5+16,"") -> 46282 | J24: =IF(I24="",0,SUMIFS(Vendas!$F$5:$F$1004,Vendas!$A$5:$A$1004,I24)) -> 0
A25: =IF(Produtos!A9="","",Produtos!A9) | B25: =IF(A25="","",SUMIFS(Vendas!$C$5:$C$1004,Vendas!$B$5:$B$1004,A25,Vendas!$A$5:$A$1004,">="&$C$5,Vendas!$A$5:$A$1004,"<"&$D$5)) | C25: =IF(A25="","",SUMIFS(Vendas!$F$5:$F$1004,Vendas!$B$5:$B$1004,A25,Vendas!$A$5:$A$1004,">="&$C$5,Vendas!$A$5:$A$1004,"<"&$D$5)) | D25: =IF(A25="","",SUMIFS(Vendas!$I$5:$I$1004,Vendas!$B$5:$B$1004,A25,Vendas!$A$5:$A$1004,">="&$C$5,Vendas!$A$5:$A$1004,"<"&$D$5)) | E25: =IF(OR(A25="",$B$8=0),"",C25/$B$8) | F25: =IF(A25="","",Produtos!E9) | I25: =IF(MONTH($C$5+17)=MONTH($C$5),$C$5+17,"") -> 46283 | J25: =IF(I25="",0,SUMIFS(Vendas!$F$5:$F$1004,Vendas!$A$5:$A$1004,I25)) -> 0
A26: =IF(Produtos!A10="","",Produtos!A10) | B26: =IF(A26="","",SUMIFS(Vendas!$C$5:$C$1004,Vendas!$B$5:$B$1004,A26,Vendas!$A$5:$A$1004,">="&$C$5,Vendas!$A$5:$A$1004,"<"&$D$5)) | C26: =IF(A26="","",SUMIFS(Vendas!$F$5:$F$1004,Vendas!$B$5:$B$1004,A26,Vendas!$A$5:$A$1004,">="&$C$5,Vendas!$A$5:$A$1004,"<"&$D$5)) | D26: =IF(A26="","",SUMIFS(Vendas!$I$5:$I$1004,Vendas!$B$5:$B$1004,A26,Vendas!$A$5:$A$1004,">="&$C$5,Vendas!$A$5:$A$1004,"<"&$D$5)) | E26: =IF(OR(A26="",$B$8=0),"",C26/$B$8) | F26: =IF(A26="","",Produtos!E10) | I26: =IF(MONTH($C$5+18)=MONTH($C$5),$C$5+18,"") -> 46284 | J26: =IF(I26="",0,SUMIFS(Vendas!$F$5:$F$1004,Vendas!$A$5:$A$1004,I26)) -> 0
A27: =IF(Produtos!A11="","",Produtos!A11) | B27: =IF(A27="","",SUMIFS(Vendas!$C$5:$C$1004,Vendas!$B$5:$B$1004,A27,Vendas!$A$5:$A$1004,">="&$C$5,Vendas!$A$5:$A$1004,"<"&$D$5)) | C27: =IF(A27="","",SUMIFS(Vendas!$F$5:$F$1004,Vendas!$B$5:$B$1004,A27,Vendas!$A$5:$A$1004,">="&$C$5,Vendas!$A$5:$A$1004,"<"&$D$5)) | D27: =IF(A27="","",SUMIFS(Vendas!$I$5:$I$1004,Vendas!$B$5:$B$1004,A27,Vendas!$A$5:$A$1004,">="&$C$5,Vendas!$A$5:$A$1004,"<"&$D$5)) | E27: =IF(OR(A27="",$B$8=0),"",C27/$B$8) | F27: =IF(A27="","",Produtos!E11) | I27: =IF(MONTH($C$5+19)=MONTH($C$5),$C$5+19,"") -> 46285 | J27: =IF(I27="",0,SUMIFS(Vendas!$F$5:$F$1004,Vendas!$A$5:$A$1004,I27)) -> 0
A28: =IF(Produtos!A12="","",Produtos!A12) | B28: =IF(A28="","",SUMIFS(Vendas!$C$5:$C$1004,Vendas!$B$5:$B$1004,A28,Vendas!$A$5:$A$1004,">="&$C$5,Vendas!$A$5:$A$1004,"<"&$D$5)) | C28: =IF(A28="","",SUMIFS(Vendas!$F$5:$F$1004,Vendas!$B$5:$B$1004,A28,Vendas!$A$5:$A$1004,">="&$C$5,Vendas!$A$5:$A$1004,"<"&$D$5)) | D28: =IF(A28="","",SUMIFS(Vendas!$I$5:$I$1004,Vendas!$B$5:$B$1004,A28,Vendas!$A$5:$A$1004,">="&$C$5,Vendas!$A$5:$A$1004,"<"&$D$5)) | E28: =IF(OR(A28="",$B$8=0),"",C28/$B$8) | F28: =IF(A28="","",Produtos!E12) | I28: =IF(MONTH($C$5+20)=MONTH($C$5),$C$5+20,"") -> 46286 | J28: =IF(I28="",0,SUMIFS(Vendas!$F$5:$F$1004,Vendas!$A$5:$A$1004,I28)) -> 0
A29: =IF(Produtos!A13="","",Produtos!A13) | B29: =IF(A29="","",SUMIFS(Vendas!$C$5:$C$1004,Vendas!$B$5:$B$1004,A29,Vendas!$A$5:$A$1004,">="&$C$5,Vendas!$A$5:$A$1004,"<"&$D$5)) | C29: =IF(A29="","",SUMIFS(Vendas!$F$5:$F$1004,Vendas!$B$5:$B$1004,A29,Vendas!$A$5:$A$1004,">="&$C$5,Vendas!$A$5:$A$1004,"<"&$D$5)) | D29: =IF(A29="","",SUMIFS(Vendas!$I$5:$I$1004,Vendas!$B$5:$B$1004,A29,Vendas!$A$5:$A$1004,">="&$C$5,Vendas!$A$5:$A$1004,"<"&$D$5)) | E29: =IF(OR(A29="",$B$8=0),"",C29/$B$8) | F29: =IF(A29="","",Produtos!E13) | I29: =IF(MONTH($C$5+21)=MONTH($C$5),$C$5+21,"") -> 46287 | J29: =IF(I29="",0,SUMIFS(Vendas!$F$5:$F$1004,Vendas!$A$5:$A$1004,I29)) -> 0
A30: =IF(Produtos!A14="","",Produtos!A14) | B30: =IF(A30="","",SUMIFS(Vendas!$C$5:$C$1004,Vendas!$B$5:$B$1004,A30,Vendas!$A$5:$A$1004,">="&$C$5,Vendas!$A$5:$A$1004,"<"&$D$5)) | C30: =IF(A30="","",SUMIFS(Vendas!$F$5:$F$1004,Vendas!$B$5:$B$1004,A30,Vendas!$A$5:$A$1004,">="&$C$5,Vendas!$A$5:$A$1004,"<"&$D$5)) | D30: =IF(A30="","",SUMIFS(Vendas!$I$5:$I$1004,Vendas!$B$5:$B$1004,A30,Vendas!$A$5:$A$1004,">="&$C$5,Vendas!$A$5:$A$1004,"<"&$D$5)) | E30: =IF(OR(A30="",$B$8=0),"",C30/$B$8) | F30: =IF(A30="","",Produtos!E14) | I30: =IF(MONTH($C$5+22)=MONTH($C$5),$C$5+22,"") -> 46288 | J30: =IF(I30="",0,SUMIFS(Vendas!$F$5:$F$1004,Vendas!$A$5:$A$1004,I30)) -> 0
A31: =IF(Produtos!A15="","",Produtos!A15) | B31: =IF(A31="","",SUMIFS(Vendas!$C$5:$C$1004,Vendas!$B$5:$B$1004,A31,Vendas!$A$5:$A$1004,">="&$C$5,Vendas!$A$5:$A$1004,"<"&$D$5)) | C31: =IF(A31="","",SUMIFS(Vendas!$F$5:$F$1004,Vendas!$B$5:$B$1004,A31,Vendas!$A$5:$A$1004,">="&$C$5,Vendas!$A$5:$A$1004,"<"&$D$5)) | D31: =IF(A31="","",SUMIFS(Vendas!$I$5:$I$1004,Vendas!$B$5:$B$1004,A31,Vendas!$A$5:$A$1004,">="&$C$5,Vendas!$A$5:$A$1004,"<"&$D$5)) | E31: =IF(OR(A31="",$B$8=0),"",C31/$B$8) | F31: =IF(A31="","",Produtos!E15) | I31: =IF(MONTH($C$5+23)=MONTH($C$5),$C$5+23,"") -> 46289 | J31: =IF(I31="",0,SUMIFS(Vendas!$F$5:$F$1004,Vendas!$A$5:$A$1004,I31)) -> 0
A32: =IF(Produtos!A16="","",Produtos!A16) | B32: =IF(A32="","",SUMIFS(Vendas!$C$5:$C$1004,Vendas!$B$5:$B$1004,A32,Vendas!$A$5:$A$1004,">="&$C$5,Vendas!$A$5:$A$1004,"<"&$D$5)) | C32: =IF(A32="","",SUMIFS(Vendas!$F$5:$F$1004,Vendas!$B$5:$B$1004,A32,Vendas!$A$5:$A$1004,">="&$C$5,Vendas!$A$5:$A$1004,"<"&$D$5)) | D32: =IF(A32="","",SUMIFS(Vendas!$I$5:$I$1004,Vendas!$B$5:$B$1004,A32,Vendas!$A$5:$A$1004,">="&$C$5,Vendas!$A$5:$A$1004,"<"&$D$5)) | E32: =IF(OR(A32="",$B$8=0),"",C32/$B$8) | F32: =IF(A32="","",Produtos!E16) | I32: =IF(MONTH($C$5+24)=MONTH($C$5),$C$5+24,"") -> 46290 | J32: =IF(I32="",0,SUMIFS(Vendas!$F$5:$F$1004,Vendas!$A$5:$A$1004,I32)) -> 0
A33: =IF(Produtos!A17="","",Produtos!A17) | B33: =IF(A33="","",SUMIFS(Vendas!$C$5:$C$1004,Vendas!$B$5:$B$1004,A33,Vendas!$A$5:$A$1004,">="&$C$5,Vendas!$A$5:$A$1004,"<"&$D$5)) | C33: =IF(A33="","",SUMIFS(Vendas!$F$5:$F$1004,Vendas!$B$5:$B$1004,A33,Vendas!$A$5:$A$1004,">="&$C$5,Vendas!$A$5:$A$1004,"<"&$D$5)) | D33: =IF(A33="","",SUMIFS(Vendas!$I$5:$I$1004,Vendas!$B$5:$B$1004,A33,Vendas!$A$5:$A$1004,">="&$C$5,Vendas!$A$5:$A$1004,"<"&$D$5)) | E33: =IF(OR(A33="",$B$8=0),"",C33/$B$8) | F33: =IF(A33="","",Produtos!E17) | I33: =IF(MONTH($C$5+25)=MONTH($C$5),$C$5+25,"") -> 46291 | J33: =IF(I33="",0,SUMIFS(Vendas!$F$5:$F$1004,Vendas!$A$5:$A$1004,I33)) -> 0
A34: =IF(Produtos!A18="","",Produtos!A18) | B34: =IF(A34="","",SUMIFS(Vendas!$C$5:$C$1004,Vendas!$B$5:$B$1004,A34,Vendas!$A$5:$A$1004,">="&$C$5,Vendas!$A$5:$A$1004,"<"&$D$5)) | C34: =IF(A34="","",SUMIFS(Vendas!$F$5:$F$1004,Vendas!$B$5:$B$1004,A34,Vendas!$A$5:$A$1004,">="&$C$5,Vendas!$A$5:$A$1004,"<"&$D$5)) | D34: =IF(A34="","",SUMIFS(Vendas!$I$5:$I$1004,Vendas!$B$5:$B$1004,A34,Vendas!$A$5:$A$1004,">="&$C$5,Vendas!$A$5:$A$1004,"<"&$D$5)) | E34: =IF(OR(A34="",$B$8=0),"",C34/$B$8) | F34: =IF(A34="","",Produtos!E18) | I34: =IF(MONTH($C$5+26)=MONTH($C$5),$C$5+26,"") -> 46292 | J34: =IF(I34="",0,SUMIFS(Vendas!$F$5:$F$1004,Vendas!$A$5:$A$1004,I34)) -> 0
A35: =IF(Produtos!A19="","",Produtos!A19) | B35: =IF(A35="","",SUMIFS(Vendas!$C$5:$C$1004,Vendas!$B$5:$B$1004,A35,Vendas!$A$5:$A$1004,">="&$C$5,Vendas!$A$5:$A$1004,"<"&$D$5)) | C35: =IF(A35="","",SUMIFS(Vendas!$F$5:$F$1004,Vendas!$B$5:$B$1004,A35,Vendas!$A$5:$A$1004,">="&$C$5,Vendas!$A$5:$A$1004,"<"&$D$5)) | D35: =IF(A35="","",SUMIFS(Vendas!$I$5:$I$1004,Vendas!$B$5:$B$1004,A35,Vendas!$A$5:$A$1004,">="&$C$5,Vendas!$A$5:$A$1004,"<"&$D$5)) | E35: =IF(OR(A35="",$B$8=0),"",C35/$B$8) | F35: =IF(A35="","",Produtos!E19) | I35: =IF(MONTH($C$5+27)=MONTH($C$5),$C$5+27,"") -> 46293 | J35: =IF(I35="",0,SUMIFS(Vendas!$F$5:$F$1004,Vendas!$A$5:$A$1004,I35)) -> 0
A36: =IF(Produtos!A20="","",Produtos!A20) | B36: =IF(A36="","",SUMIFS(Vendas!$C$5:$C$1004,Vendas!$B$5:$B$1004,A36,Vendas!$A$5:$A$1004,">="&$C$5,Vendas!$A$5:$A$1004,"<"&$D$5)) | C36: =IF(A36="","",SUMIFS(Vendas!$F$5:$F$1004,Vendas!$B$5:$B$1004,A36,Vendas!$A$5:$A$1004,">="&$C$5,Vendas!$A$5:$A$1004,"<"&$D$5)) | D36: =IF(A36="","",SUMIFS(Vendas!$I$5:$I$1004,Vendas!$B$5:$B$1004,A36,Vendas!$A$5:$A$1004,">="&$C$5,Vendas!$A$5:$A$1004,"<"&$D$5)) | E36: =IF(OR(A36="",$B$8=0),"",C36/$B$8) | F36: =IF(A36="","",Produtos!E20) | I36: =IF(MONTH($C$5+28)=MONTH($C$5),$C$5+28,"") -> 46294 | J36: =IF(I36="",0,SUMIFS(Vendas!$F$5:$F$1004,Vendas!$A$5:$A$1004,I36)) -> 0
A37: =IF(Produtos!A21="","",Produtos!A21) | B37: =IF(A37="","",SUMIFS(Vendas!$C$5:$C$1004,Vendas!$B$5:$B$1004,A37,Vendas!$A$5:$A$1004,">="&$C$5,Vendas!$A$5:$A$1004,"<"&$D$5)) | C37: =IF(A37="","",SUMIFS(Vendas!$F$5:$F$1004,Vendas!$B$5:$B$1004,A37,Vendas!$A$5:$A$1004,">="&$C$5,Vendas!$A$5:$A$1004,"<"&$D$5)) | D37: =IF(A37="","",SUMIFS(Vendas!$I$5:$I$1004,Vendas!$B$5:$B$1004,A37,Vendas!$A$5:$A$1004,">="&$C$5,Vendas!$A$5:$A$1004,"<"&$D$5)) | E37: =IF(OR(A37="",$B$8=0),"",C37/$B$8) | F37: =IF(A37="","",Produtos!E21) | I37: =IF(MONTH($C$5+29)=MONTH($C$5),$C$5+29,"") -> 46295 | J37: =IF(I37="",0,SUMIFS(Vendas!$F$5:$F$1004,Vendas!$A$5:$A$1004,I37)) -> 0
A38: =IF(Produtos!A22="","",Produtos!A22) | B38: =IF(A38="","",SUMIFS(Vendas!$C$5:$C$1004,Vendas!$B$5:$B$1004,A38,Vendas!$A$5:$A$1004,">="&$C$5,Vendas!$A$5:$A$1004,"<"&$D$5)) | C38: =IF(A38="","",SUMIFS(Vendas!$F$5:$F$1004,Vendas!$B$5:$B$1004,A38,Vendas!$A$5:$A$1004,">="&$C$5,Vendas!$A$5:$A$1004,"<"&$D$5)) | D38: =IF(A38="","",SUMIFS(Vendas!$I$5:$I$1004,Vendas!$B$5:$B$1004,A38,Vendas!$A$5:$A$1004,">="&$C$5,Vendas!$A$5:$A$1004,"<"&$D$5)) | E38: =IF(OR(A38="",$B$8=0),"",C38/$B$8) | F38: =IF(A38="","",Produtos!E22) | I38: =IF(MONTH($C$5+30)=MONTH($C$5),$C$5+30,"") | J38: =IF(I38="",0,SUMIFS(Vendas!$F$5:$F$1004,Vendas!$A$5:$A$1004,I38)) -> 0
A39: =IF(Produtos!A23="","",Produtos!A23) | B39: =IF(A39="","",SUMIFS(Vendas!$C$5:$C$1004,Vendas!$B$5:$B$1004,A39,Vendas!$A$5:$A$1004,">="&$C$5,Vendas!$A$5:$A$1004,"<"&$D$5)) | C39: =IF(A39="","",SUMIFS(Vendas!$F$5:$F$1004,Vendas!$B$5:$B$1004,A39,Vendas!$A$5:$A$1004,">="&$C$5,Vendas!$A$5:$A$1004,"<"&$D$5)) | D39: =IF(A39="","",SUMIFS(Vendas!$I$5:$I$1004,Vendas!$B$5:$B$1004,A39,Vendas!$A$5:$A$1004,">="&$C$5,Vendas!$A$5:$A$1004,"<"&$D$5)) | E39: =IF(OR(A39="",$B$8=0),"",C39/$B$8) | F39: =IF(A39="","",Produtos!E23)
A40: =IF(Produtos!A24="","",Produtos!A24) | B40: =IF(A40="","",SUMIFS(Vendas!$C$5:$C$1004,Vendas!$B$5:$B$1004,A40,Vendas!$A$5:$A$1004,">="&$C$5,Vendas!$A$5:$A$1004,"<"&$D$5)) | C40: =IF(A40="","",SUMIFS(Vendas!$F$5:$F$1004,Vendas!$B$5:$B$1004,A40,Vendas!$A$5:$A$1004,">="&$C$5,Vendas!$A$5:$A$1004,"<"&$D$5)) | D40: =IF(A40="","",SUMIFS(Vendas!$I$5:$I$1004,Vendas!$B$5:$B$1004,A40,Vendas!$A$5:$A$1004,">="&$C$5,Vendas!$A$5:$A$1004,"<"&$D$5)) | E40: =IF(OR(A40="",$B$8=0),"",C40/$B$8) | F40: =IF(A40="","",Produtos!E24)
A41: =IF(Produtos!A25="","",Produtos!A25) | B41: =IF(A41="","",SUMIFS(Vendas!$C$5:$C$1004,Vendas!$B$5:$B$1004,A41,Vendas!$A$5:$A$1004,">="&$C$5,Vendas!$A$5:$A$1004,"<"&$D$5)) | C41: =IF(A41="","",SUMIFS(Vendas!$F$5:$F$1004,Vendas!$B$5:$B$1004,A41,Vendas!$A$5:$A$1004,">="&$C$5,Vendas!$A$5:$A$1004,"<"&$D$5)) | D41: =IF(A41="","",SUMIFS(Vendas!$I$5:$I$1004,Vendas!$B$5:$B$1004,A41,Vendas!$A$5:$A$1004,">="&$C$5,Vendas!$A$5:$A$1004,"<"&$D$5)) | E41: =IF(OR(A41="",$B$8=0),"",C41/$B$8) | F41: =IF(A41="","",Produtos!E25)
A42: =IF(Produtos!A26="","",Produtos!A26) | B42: =IF(A42="","",SUMIFS(Vendas!$C$5:$C$1004,Vendas!$B$5:$B$1004,A42,Vendas!$A$5:$A$1004,">="&$C$5,Vendas!$A$5:$A$1004,"<"&$D$5)) | C42: =IF(A42="","",SUMIFS(Vendas!$F$5:$F$1004,Vendas!$B$5:$B$1004,A42,Vendas!$A$5:$A$1004,">="&$C$5,Vendas!$A$5:$A$1004,"<"&$D$5)) | D42: =IF(A42="","",SUMIFS(Vendas!$I$5:$I$1004,Vendas!$B$5:$B$1004,A42,Vendas!$A$5:$A$1004,">="&$C$5,Vendas!$A$5:$A$1004,"<"&$D$5)) | E42: =IF(OR(A42="",$B$8=0),"",C42/$B$8) | F42: =IF(A42="","",Produtos!E26)
A43: =IF(Produtos!A27="","",Produtos!A27) | B43: =IF(A43="","",SUMIFS(Vendas!$C$5:$C$1004,Vendas!$B$5:$B$1004,A43,Vendas!$A$5:$A$1004,">="&$C$5,Vendas!$A$5:$A$1004,"<"&$D$5)) | C43: =IF(A43="","",SUMIFS(Vendas!$F$5:$F$1004,Vendas!$B$5:$B$1004,A43,Vendas!$A$5:$A$1004,">="&$C$5,Vendas!$A$5:$A$1004,"<"&$D$5)) | D43: =IF(A43="","",SUMIFS(Vendas!$I$5:$I$1004,Vendas!$B$5:$B$1004,A43,Vendas!$A$5:$A$1004,">="&$C$5,Vendas!$A$5:$A$1004,"<"&$D$5)) | E43: =IF(OR(A43="",$B$8=0),"",C43/$B$8) | F43: =IF(A43="","",Produtos!E27)
...

Sheet Produtos
A1: Produtos
A2: Cadastre o que você vende. Preço e custo por unidade.
A4: Produto | B4: Categoria | C4: Preço de venda (R$) | D4: Custo por unidade (R$) | E4: Lucro por unidade (R$) | F4: Margem
E5: =IF(A5="","",C5-D5) | F5: =IF(OR(A5="",C5=0),"",E5/C5)
E6: =IF(A6="","",C6-D6) | F6: =IF(OR(A6="",C6=0),"",E6/C6)
E7: =IF(A7="","",C7-D7) | F7: =IF(OR(A7="",C7=0),"",E7/C7)
E8: =IF(A8="","",C8-D8) | F8: =IF(OR(A8="",C8=0),"",E8/C8)
E9: =IF(A9="","",C9-D9) | F9: =IF(OR(A9="",C9=0),"",E9/C9)
E10: =IF(A10="","",C10-D10) | F10: =IF(OR(A10="",C10=0),"",E10/C10)
E11: =IF(A11="","",C11-D11) | F11: =IF(OR(A11="",C11=0),"",E11/C11)
E12: =IF(A12="","",C12-D12) | F12: =IF(OR(A12="",C12=0),"",E12/C12)
E13: =IF(A13="","",C13-D13) | F13: =IF(OR(A13="",C13=0),"",E13/C13)
E14: =IF(A14="","",C14-D14) | F14: =IF(OR(A14="",C14=0),"",E14/C14)
E15: =IF(A15="","",C15-D15) | F15: =IF(OR(A15="",C15=0),"",E15/C15)
E16: =IF(A16="","",C16-D16) | F16: =IF(OR(A16="",C16=0),"",E16/C16)
... E44: =IF(A44="","",C44-D44) | F44: =IF(OR(A44="",C44=0),"",E44/C44)

Sheet Despesas
A1: Despesas e taxas
A2: Taxas da maquininha por forma de pagamento e as despesas do mês.
A4: Forma de pagamento | B4: Taxa (%)
A5: Pix | B5: 0 | C5: Taxas de exemplo. Confira as da sua maquininha no app dela.
A6: Dinheiro | B6: 0
A7: Débito | B7: 0.0199
A8: Crédito | B8: 0.0399
A11: DESPESAS DO MÊS
A12: Data | B12: Descrição | C12: Categoria | D12: Valor (R$)

Sheet Vendas
A1: Vendas
A2: Uma linha por venda (ou por produto da venda). Preencha só as colunas amarelo-claras.
A4: Data | B4: Produto | C4: Qtd | D4: Forma de pagamento | E4: Preço (R$) | F4: Total (R$) | G4: Custo (R$) | H4: Taxa (R$) | I4: Lucro (R$)
E5: =IF(B5="","",IFERROR(INDEX(Produtos!$C$5:$C$44,MATCH(B5,Produtos!$A$5:$A$44,0)),0)) | F5: =IF(B5="","",C5*E5) | G5: =IF(B5="","",C5*IFERROR(INDEX(Produtos!$D$5:$D$44,MATCH(B5,Produtos!$A$5:$A$44,0)),0)) | H5: =IF(B5="","",F5*IFERROR(INDEX(Despesas!$B$5:$B$8,MATCH(D5,Despesas!$A$5:$A$8,0)),0)) | I5: =IF(B5="","",F5-G5-H5)
E6: =IF(B6="","",IFERROR(INDEX(Produtos!$C$5:$C$44,MATCH(B6,Produtos!$A$5:$A$44,0)),0)) | F6: =IF(B6="","",C6*E6) | G6: =IF(B6="","",C6*IFERROR(INDEX(Produtos!$D$5:$D$44,MATCH(B6,Produtos!$A$5:$A$44,0)),0)) | H6: =IF(B6="","",F6*IFERROR(INDEX(Despesas!$B$5:$B$8,MATCH(D6,Despesas!$A$5:$A$8,0)),0)) | I6: =IF(B6="","",F6-G6-H6)
E7: =IF(B7="","",IFERROR(INDEX(Produtos!$C$5:$C$44,MATCH(B7,Produtos!$A$5:$A$44,0)),0)) | F7: =IF(B7="","",C7*E7) | G7: =IF(B7="","",C7*IFERROR(INDEX(Produtos!$D$5:$D$44,MATCH(B7,Produtos!$A$5:$A$44,0)),0)) | H7: =IF(B7="","",F7*IFERROR(INDEX(Despesas!$B$5:$B$8,MATCH(D7,Despesas!$A$5:$A$8,0)),0)) | I7: =IF(B7="","",F7-G7-H7)
E8: =IF(B8="","",IFERROR(INDEX(Produtos!$C$5:$C$44,MATCH(B8,Produtos!$A$5:$A$44,0)),0)) | F8: =IF(B8="","",C8*E8) | G8: =IF(B8="","",C8*IFERROR(INDEX(Produtos!$D$5:$D$44,MATCH(B8,Produtos!$A$5:$A$44,0)),0)) | H8: =IF(B8="","",F8*IFERROR(INDEX(Despesas!$B$5:$B$8,MATCH(D8,Despesas!$A$5:$A$8,0)),0)) | I8: =IF(B8="","",F8-G8-H8)
E9: =IF(B9="","",IFERROR(INDEX(Produtos!$C$5:$C$44,MATCH(B9,Produtos!$A$5:$A$44,0)),0)) | F9: =IF(B9="","",C9*E9) | G9: =IF(B9="","",C9*IFERROR(INDEX(Produtos!$D$5:$D$44,MATCH(B9,Produtos!$A$5:$A$44,0)),0)) | H9: =IF(B9="","",F9*IFERROR(INDEX(Despesas!$B$5:$B$8,MATCH(D9,Despesas!$A$5:$A$8,0)),0)) | I9: =IF(B9="","",F9-G9-H9)
E10: =IF(B10="","",IFERROR(INDEX(Produtos!$C$5:$C$44,MATCH(B10,Produtos!$A$5:$A$44,0)),0)) | F10: =IF(B10="","",C10*E10) | G10: =IF(B10="","",C10*IFERROR(INDEX(Produtos!$D$5:$D$44,MATCH(B10,Produtos!$A$5:$A$44,0)),0)) | H10: =IF(B10="","",F10*IFERROR(INDEX(Despesas!$B$5:$B$8,MATCH(D10,Despesas!$A$5:$A$8,0)),0)) | I10: =IF(B10="","",F10-G10-H10)
E11: =IF(B11="","",IFERROR(INDEX(Produtos!$C$5:$C$44,MATCH(B11,Produtos!$A$5:$A$44,0)),0)) | F11: =IF(B11="","",C11*E11) | G11: =IF(B11="","",C11*IFERROR(INDEX(Produtos!$D$5:$D$44,MATCH(B11,Produtos!$A$5:$A$44,0)),0)) | H11: =IF(B11="","",F11*IFERROR(INDEX(Despesas!$B$5:$B$8,MATCH(D11,Despesas!$A$5:$A$8,0)),0)) | I11: =IF(B11="","",F11-G11-H11)
E12: =IF(B12="","",IFERROR(INDEX(Produtos!$C$5:$C$44,MATCH(B12,Produtos!$A$5:$A$44,0)),0)) | F12: =IF(B12="","",C12*E12) | G12: =IF(B12="","",C12*IFERROR(INDEX(Produtos!$D$5:$D$44,MATCH(B12,Produtos!$A$5:$A$44,0)),0)) | H12: =IF(B12="","",F12*IFERROR(INDEX(Despesas!$B$5:$B$8,MATCH(D12,Despesas!$A$5:$A$8,0)),0)) | I12: =IF(B12="","",F12-G12-H12)
E13: =IF(B13="","",IFERROR(INDEX(Produtos!$C$5:$C$44,MATCH(B13,Produtos!$A$5:$A$44,0)),0)) | F13: =IF(B13="","",C13*E13) | G13: =IF(B13="","",C13*IFERROR(INDEX(Produtos!$D$5:$D$44,MATCH(B13,Produtos!$A$5:$A$44,0)),0)) | H13: =IF(B13="","",F13*IFERROR(INDEX(Despesas!$B$5:$B$8,MATCH(D13,Despesas!$A$5:$A$8,0)),0)) | I13: =IF(B13="","",F13-G13-H13)
E14: =IF(B14="","",IFERROR(INDEX(Produtos!$C$5:$C$44,MATCH(B14,Produtos!$A$5:$A$44,0)),0)) | F14: =IF(B14="","",C14*E14) | G14: =IF(B14="","",C14*IFERROR(INDEX(Produtos!$D$5:$D$44,MATCH(B14,Produtos!$A$5:$A$44,0)),0)) | H14: =IF(B14="","",F14*IFERROR(INDEX(Despesas!$B$5:$B$8,MATCH(D14,Despesas!$A$5:$A$8,0)),0)) | I14: =IF(B14="","",F14-G14-H14)
E15: =IF(B15="","",IFERROR(INDEX(Produtos!$C$5:$C$44,MATCH(B15,Produtos!$A$5:$A$44,0)),0)) | F15: =IF(B15="","",C15*E15) | G15: =IF(B15="","",C15*IFERROR(INDEX(Produtos!$D$5:$D$44,MATCH(B15,Produtos!$A$5:$A$44,0)),0)) | H15: =IF(B15="","",F15*IFERROR(INDEX(Despesas!$B$5:$B$8,MATCH(D15,Despesas!$A$5:$A$8,0)),0)) | I15: =IF(B15="","",F15-G15-H15)
E16: =IF(B16="","",IFERROR(INDEX(Produtos!$C$5:$C$44,MATCH(B16,Produtos!$A$5:$A$44,0)),0)) | F16: =IF(B16="","",C16*E16) | G16: =IF(B16="","",C16*IFERROR(INDEX(Produtos!$D$5:$D$44,MATCH(B16,Produtos!$A$5:$A$44,0)),0)) | H16: =IF(B16="","",F16*IFERROR(INDEX(Despesas!$B$5:$B$8,MATCH(D16,Despesas!$A$5:$A$8,0)),0)) | I16: =IF(B16="","",F16-G16-H16)
... E1004: =IF(B1004="","",IFERROR(INDEX(Produtos!$C$5:$C$44,MATCH(B1004,Produtos!$A$5:$A$44,0)),0)) | F1004: =IF(B1004="","",C1004*E1004) | G1004: =IF(B1004="","",C1004*IFERROR(INDEX(Produtos!$D$5:$D$44,MATCH(B1004,Produtos!$A$5:$A$44,0)),0)) | H1004: =IF(B1004="","",F1004*IFERROR(INDEX(Despesas!$B$5:$B$8,MATCH(D1004,Despesas!$A$5:$A$8,0)),0)) | I1004: =IF(B1004="","",F1004-G1004-H1004)
